Workbook
Name 切片器_LEL: #N/A
Name 切片器_LEL1: #N/A
Name 切片器_LEL2: #N/A
Name 切片器_LEL3: #N/A
Name 切片器_产品品规: #N/A
Name 切片器_核心医院: #N/A
Name 切片器_医院分层: #N/A
Name 切片器_医院分层1: #N/A
Name 切片器_医院分层11: #N/A
Name 切片器_医院分层2: #N/A

Sheet 业绩
L2: 当月SU
K3: 江西一圈Herceptin IV | L3: 37
A4: 行标签 | B4: 求和项:26Q1TV | C4: 求和项:26Q1SV | D4: 求和项:Q1达成 | E4: 求和项:Q1渗透率 | K4: 江西一圈Herceptin SC | L4: 39
A5: 策略 | B5: 57240776 | C5: 62889952 | D5: 1.0986915 | E5: 0.49690648 | K5: 江西一圈Itovebi 3mg | L5: 5
A6: Itovebi | B6: 2148872.7 | C6: 4425427.6 | D6: 2.0594182 | E6: #DIV/0! | K6: 江西一圈Itovebi 9mg | L6: 4
A7: Phesgo | B7: 55091903 | C7: 58464525 | D7: 1.0612181 | E7: 0.49690648 | K7: 江西一圈Perjeta | L7: 3
A8: 成熟 | B8: 54229016 | C8: 53417284 | D8: 0.98503141 | E8: #DIV/0! | K8: 江西一圈Phesgo 10ml | L8: 147
A9: Herceptin IV | B9: 16724355 | C9: 15747256 | D9: 0.94157627 | E9: #DIV/0! | K9: 江西一圈Phesgo 15ml | L9: 6
A10: Herceptin SC | B10: 16757833 | C10: 14356634 | D10: 0.85671188 | E10: #DIV/0! | K10: 林丽贞Herceptin IV | L10: 120
A11: Perjeta | B11: 20746828 | C11: 23313393 | D11: 1.1237088 | E11: #DIV/0! | K11: 林丽贞Herceptin SC | L11: 29
A12: 总计 | B12: 1.1146979e+08 | C12: 1.1630724e+08 | D12: 1.0433969 | E12: 0.49690648 | K12: 林丽贞Itovebi 3mg | L12: 4
K13: 林丽贞Itovebi 9mg | L13: 5
K14: 林丽贞Perjeta | L14: 134
K15: 林丽贞Phesgo 10ml | L15: 152
A16: 行标签 | B16: 求和项:26Q1TV | C16: 求和项:26Q1SV | D16: 求和项:Q1达成 | E16: 求和项:Q1渗透率 | K16: 林丽贞Phesgo 15ml | L16: 8
A17: 江西一圈 | B17: 11480073 | C17: 12782342 | D17: 1.1134374 | E17: 0.50839092 | K17: 周小英Herceptin IV | L17: 131
A18: 策略 | B18: 7079143.1 | C18: 9742046.6 | D18: 1.3761618 | E18: 0.50839092 | K18: 周小英Herceptin SC | L18: 386
A19: 成熟 | B19: 4400929.6 | C19: 3040295.4 | D19: 0.69083028 | E19: #DIV/0! | K19: 周小英Itovebi 3mg | L19: 14
A20: 林丽贞 | B20: 16144653 | C20: 17054545 | D20: 1.0563587 | E20: 0.33670482 | K20: 周小英Itovebi 9mg | L20: 7
A21: 策略 | B21: 8694026.2 | C21: 8018690.5 | D21: 0.92232187 | E21: 0.33670482 | K21: 周小英Perjeta | L21: 297
A22: 成熟 | B22: 7450627.2 | C22: 9035854.4 | D22: 1.2127643 | E22: #DIV/0! | K22: 周小英Phesgo 10ml | L22: 214
A23: 唐晓玉 | B23: 9085236.4 | C23: 8969998.4 | D23: 0.9873159 | E23: 0.33409524 | K23: 周小英Phesgo 15ml | L23: 3
A24: 策略 | B24: 3415337.6 | C24: 5638056.5 | D24: 1.650805 | E24: 0.33409524 | K24: 唐晓玉Herceptin IV | L24: 27
A25: 成熟 | B25: 5669898.8 | C25: 3331941.9 | D25: 0.58765457 | E25: #DIV/0! | K25: 唐晓玉Herceptin SC | L25: 38
A26: 许辉容 | B26: 17468184 | C26: 14629352 | D26: 0.83748558 | E26: 0.34956347 | K26: 唐晓玉Itovebi 3mg | L26: 3
A27: 策略 | B27: 7952534.6 | C27: 6829535.8 | D27: 0.85878731 | E27: 0.34956347 | K27: 唐晓玉Itovebi 9mg | L27: 11
A28: 成熟 | B28: 9515649.8 | C28: 7799816.7 | D28: 0.81968304 | E28: #DIV/0! | K28: 唐晓玉Perjeta | L28: 25
A29: 钟明珠 | B29: 22251589 | C29: 21843880 | D29: 0.98167734 | E29: 0.63282863 | K29: 唐晓玉Phesgo 10ml | L29: 112
A30: 策略 | B30: 11130936 | C30: 12074585 | D30: 1.0847771 | E30: 0.63282863 | K30: 唐晓玉Phesgo 15ml | L30: 3
A31: 成熟 | B31: 11120653 | C31: 9769295.6 | D31: 0.87848221 | E31: #DIV/0! | K31: 许辉容Herceptin IV | L31: 196
A32: 周小英 | B32: 35040056 | C32: 38977201 | D32: 1.1123612 | E32: 0.71825024 | K32: 许辉容Herceptin SC | L32: 65
A33: 策略 | B33: 18968799 | C33: 19862101 | D33: 1.0470932 | E33: 0.71825024 | K33: 许辉容Itovebi 3mg | L33: 10
A34: 成熟 | B34: 16071257 | C34: 19115100 | D34: 1.1893967 | E34: #DIV/0! | K34: 许辉容Itovebi 9mg | L34: 2
A35: 总计 | B35: 1.1146979e+08 | C35: 1.1425732e+08 | D35: 1.025007 | E35: 0.49194662 | K35: 许辉容Perjeta | L35: 82
K36: 许辉容Phesgo 10ml | L36: 111
K37: 许辉容Phesgo 15ml | L37: 12
K38: 钟明珠Herceptin IV | L38: 108
K39: 钟明珠Herceptin SC | L39: 138
K40: 钟明珠Itovebi 3mg | L40: 31
K41: 钟明珠Itovebi 9mg | L41: 31
...

Sheet DDI
B1: 时间进度 | C1: =大妥进度!Q1/大妥进度!R1 -> 0.85714286 | M1: 截止27日 | N1: 截止27日 | Q1: landing | X1: =X3+Z3 -> 5905378 | Y1: =X1/V3 -> 0.87341419 | AB1: Q2-月 | AN1: 季度
A2: Link | B2: LEL姓名 | C2: 产品品规 | D2: 考核价 | E2: 2604TU | F2: 2604SU | G2: 2604DDI | H2: 预估达成 | I2: DDI达成 | J2: 完成预估进度 | K2: GAP | L2: 27日SU | M2: DDI达成 | N2: GAP | O2: 当天 | P2: 28-30SU | Q2: DDI达成 | R2: GAP | S2: 28日 | T2: 29日 | U2: 30日 | V2: 2604TV | W2: 2604SV | X2: 2604DDI | Y2: 当天SV | Z2: 28-30SV | AB2: 产品 | AC2: (全部) | AN2: 产品 | AO2: (全部) | BD2: 当月SU
B3: 江西省 | C3: 全产品 | E3: =SUM(E16,E29) -> 0 | F3: =SUM(F16,F29) -> 0 | G3: =SUM(G16,G29) -> 0 | H3: =IFERROR(W3/V3,"") -> 0.96001265 | I3: =IFERROR(X3/V3,"") -> 0.87341419 | J3: =IFERROR(X3/W3,"") -> 0.90979446 | K3: =(X3-W3)/10000 -> -58.551447 | L3: =Y3/10000 -> 122.1568 | M3: =IFERROR((X3+Y3)/V3,"") -> 1.0540859 | N3: =K3+L3 -> 63.605354 | O3: =SUM(O16,O29) -> 0 | P3: =SUM(P16,P29) -> 0 | Q3: =IFERROR((X3+Z3)/V3,"") -> 0.87341419 | R3: =K3+P3 -> -58.551447 | S3: =SUM(S16,S29) -> 0 | T3: =SUM(T16,T29) -> 0 | U3: =SUM(U16,U29) -> 0 | V3: =SUM(V16,V29) -> 6761257.2 | W3: =SUM(W16,W29) -> 6490892.5 | X3: =SUM(X16,X29) -> 5905378 | Y3: =SUM(Y16,Y29) -> 1221568 | Z3: =SUM(Z16,Z29) -> 0 | AV3: 产品分类 | AW3: 策略 | BC3: 江西一圈Herceptin IV | BD3: 61
C4: 策略 | E4: =SUM(E17,E30) -> 0 | F4: =SUM(F17,F30) -> 0 | G4: =SUM(G17,G30) -> 0 | H4: =IFERROR(W4/V4,"") -> 1.2250167 | I4: =IFERROR(X4/V4,"") -> 1.0499781 | J4: =IFERROR(X4/W4,"") -> 0.85711327 | K4: =(X4-W4)/10000 -> -67.664989 | L4: =Y4/10000 -> 100.08617 | M4: =IFERROR((X4+Y4)/V4,"") -> 1.3088852 | N4: =K4+L4 -> 32.421184 | O4: =SUM(O17,O30) -> 0 | P4: =SUM(P17,P30) -> 0 | Q4: =IFERROR((X4+Z4)/V4,"") -> 1.0499781 | R4: =K4+P4 -> -67.664989 | S4: =SUM(S17,S30) -> 0 | T4: =SUM(T17,T30) -> 0 | U4: =SUM(U17,U30) -> 0 | V4: =SUM(V17,V30) -> 3865717.4 | W4: =SUM(W17,W30) -> 4735568.5 | X4: =SUM(X17,X30) -> 4058918.7 | Y4: =SUM(Y17,Y30) -> 1000861.7 | Z4: =SUM(Z17,Z30) -> 0 | AC4: 列标签 | AO4: 列标签 | AV4: 产品 | AW4: (全部) | BC4: 江西一圈Herceptin SC | BD4: 88
C5: HF | E5: =SUM(E18,E31) -> 1046.0651 | F5: =SUM(F18,F31) -> 972.75908 | G5: =SUM(G18,G31) -> 912 | H5: =IFERROR(W5/V5,"") -> 1.0123355 | I5: =IFERROR(X5/V5,"") -> 0.92384111 | J5: =IFERROR(X5/W5,"") -> 0.91258392 | K5: =G5-F5 -> -60.759081 | L5: =O5 -> 168 | M5: =IFERROR((X5+Y5)/V5,"") -> 1.1112121 | N5: =K5+L5 -> 107.24092 | O5: =SUM(O18,O31) -> 168 | P5: =SUM(P18,P31) -> 0 | Q5: =IFERROR((X5+Z5)/V5,"") -> 0.92384111 | R5: =K5+P5 -> -60.759081 | S5: =SUM(S18,S31) -> 0 | T5: =SUM(T18,T31) -> 0 | U5: =SUM(U18,U31) -> 0 | V5: =SUM(V18,V31) -> 5433506.9 | W5: =SUM(W18,W31) -> 5500532 | X5: =SUM(X18,X31) -> 5019697 | Y5: =SUM(Y18,Y31) -> 1018081.4 | Z5: =SUM(Z18,Z31) -> 0 | AC5: 4月 | AE5: 5月 | AG5: 6月 | AI5: 4月汇总 | AJ5: 5月汇总 | AK5: 6月汇总 | AO5: 策略 | AQ5: 成熟 | AS5: Q1达成汇总 | AT5: Q2达成汇总 | BC5: 江西一圈Itovebi 3mg | BD5: 6
C6: PF | E6: =SUM(E19,E32) -> 922.16906 | F6: =SUM(F19,F32) -> 913.75908 | G6: =SUM(G19,G32) -> 786 | H6: =IFERROR(W6/V6,"") -> 1.0449367 | I6: =IFERROR(X6/V6,"") -> 0.89648342 | J6: =IFERROR(X6/W6,"") -> 0.85793087 | K6: =G6-F6 -> -127.75908 | L6: =O6 -> 201 | M6: =IFERROR((X6+Y6)/V6,"") -> 1.1279016 | N6: =K6+L6 -> 73.240919 | O6: =SUM(O19,O32) -> 201 | P6: =SUM(P19,P32) -> 0 | Q6: =IFERROR((X6+Z6)/V6,"") -> 0.89648342 | R6: =K6+P6 -> -127.75908 | S6: =SUM(S19,S32) -> 0 | T6: =SUM(T19,T32) -> 0 | U6: =SUM(U19,U32) -> 0 | V6: =SUM(V19,V32) -> 4926838.6 | W6: =SUM(W19,W32) -> 5148234.3 | X6: =SUM(X19,X32) -> 4416829.1 | Y6: =SUM(Y19,Y32) -> 1140160 | Z6: =SUM(Z19,Z32) -> 0 | AB6: 行标签 | AC6: 策略 | AD6: 成熟 | AE6: 策略 | AF6: 成熟 | AG6: 策略 | AH6: 成熟 | AN6: 行标签 | AO6: Q1达成 | AP6: Q2达成 | AQ6: Q1达成 | AR6: Q2达成 | AV6: 行标签 | AW6: Q1达成 | AX6: Q1渗透率 | AY6: Q2达成 | AZ6: Q2渗透率 | BC6: 江西一圈Itovebi 9mg | BD6: 6
C7: P-折算10ml | E7: =SUM(E20,E33) -> 622.50154 | F7: =SUM(F20,F33) -> 737.75908 | G7: =SUM(G20,G33) -> 630 | H7: =IFERROR(W7/V7,"") -> 1.191383 | I7: =IFERROR(X7/V7,"") -> 1.0167802 | J7: =IFERROR(X7/W7,"") -> 0.85344532 | K7: =G7-F7 -> -107.75908 | L7: =O7 -> 158 | M7: =IFERROR((X7+Y7)/V7,"") -> 1.2763362 | N7: =K7+L7 -> 50.240919 | O7: =SUM(O20,O33) -> 158 | P7: =SUM(P20,P33) -> 0 | Q7: =IFERROR((X7+Z7)/V7,"") -> 1.0167802 | R7: =K7+P7 -> -107.75908 | S7: =SUM(S20,S33) -> 0 | T7: =SUM(T20,T33) -> 0 | U7: =SUM(U20,U33) -> 0 | V7: =SUM(V20,V33) -> 3732402.8 | W7: =SUM(W20,W33) -> 4446721.2 | X7: =SUM(X20,X33) -> 3795033.4 | Y7: =SUM(Y20,Y33) -> 968767.58 | Z7: =SUM(Z20,Z33) -> 0 | AB7: 江西一圈 | AC7: 0.77409878 | AD7: 0.46585694 | AE7: 0 | AF7: 0 | AG7: 0 | AH7: 0 | AI7: 0.66914581 | AJ7: 0 | AK7: 0 | AN7: 江西一圈 | AO7: 1.3761618 | AP7: 0.24704077 | AQ7: 0.69083028 | AR7: 0.13804648 | AS7: 1.1134374 | AT7: 0.20809389 | AV7: 江西一圈 | AW7: 1.3761618 | AX7: 0.50839092 | AY7: 0.24704077 | AZ7: 0.10694307 | BC7: 江西一圈Perjeta | BD7: 29
C8: I-折算9mg | E8: =SUM(E21,E34) -> 12.461569 | F8: =SUM(F21,F34) -> 27 | G8: =SUM(G21,G34) -> 24.666667 | H8: =IFERROR(W8/V8,"") -> 2.1666594 | I8: =IFERROR(X8/V8,"") -> 1.9794174 | J8: =IFERROR(X8/W8,"") -> 0.91358031 | K8: =G8-F8 -> -2.3333333 | L8: =O8 -> 3 | M8: =IFERROR((X8+Y8)/V8,"") -> 2.2201573 | N8: =K8+L8 -> 0.66666667 | O8: =SUM(O21,O34) -> 3 | P8: =SUM(P21,P34) -> 0 | Q8: =IFERROR((X8+Z8)/V8,"") -> 1.9794174 | R8: =K8+P8 -> -2.3333333 | S8: =SUM(S21,S34) -> 0 | T8: =SUM(T21,T34) -> 0 | U8: =SUM(U21,U34) -> 0 | V8: =SUM(V21,V34) -> 133314.62 | W8: =SUM(W21,W34) -> 288847.37 | X8: =SUM(X21,X34) -> 263885.27 | Y8: =SUM(Y21,Y34) -> 32094.15 | Z8: =SUM(Z21,Z34) -> 0 | AB8: 冯新华 | AC8: 0.98130051 | AD8: 1.0492806 | AE8: 0 | AF8: 0 | AG8: 0 | AH8: 0 | AI8: 0.99658944 | AJ8: 0 | AK8: 0 | AN8: 冯新华 | AO8: 1.2066126 | AP8: 0.31471048 | AQ8: 0.63117296 | AR8: 0.30752126 | AS8: 1.0543362 | AT8: 0.31297791 | AV8: 冯新华 | AW8: 1.2066126 | AX8: 0.54477612 | AY8: 0.31471048 | AZ8: 0.16268657 | BC8: 江西一圈Phesgo 10ml | BD8: 290
C9: HIV | D9: 4535.5 | E9: =SUM(E22,E35) -> 105.12957 | F9: =SUM(F22,F35) -> 104 | G9: =SUM(G22,G35) -> 128 | H9: =IFERROR(W9/V9,"") -> 0.98925542 | I9: =IFERROR(X9/V9,"") -> 1.2175451 | J9: =IFERROR(X9/W9,"") -> 1.2307692 | K9: =G9-F9 -> 24 | L9: =O9 -> 1 | M9: =IFERROR((X9+Y9)/V9,"") -> 1.2270572 | N9: =K9+L9 -> 25 | O9: =SUM(O22,O35) -> 1 | P9: =SUM(P22,P35) -> 0 | Q9: =IFERROR((X9+Z9)/V9,"") -> 1.2175451 | R9: =K9+P9 -> 24 | S9: =SUM(S22,S35) -> 0 | T9: =SUM(T22,T35) -> 0 | U9: =SUM(U22,U35) -> 0 | V9: =SUM(V22,V35) -> 476815.18 | W9: =SUM(W22,W35) -> 471692 | X9: =SUM(X22,X35) -> 580544 | Y9: =SUM(Y22,Y35) -> 4535.5 | Z9: =SUM(Z22,Z35) -> 0 | AB9: 黄文萍 | AC9: 0.52477989 | AD9: 0.33556769 | AE9: 0 | AF9: 0 | AG9: 0 | AH9: 0 | AI9: 0.44927988 | AJ9: 0 | AK9: 0 | AN9: 黄文萍 | AO9: 1.8387464 | AP9: 0.16700562 | AQ9: 0.38672257 | AR9: 0.098477878 | AS9: 1.1802041 | AT9: 0.13831948 | AV9: 黄文萍 | AW9: 1.8387464 | AX9: 0.70448179 | AY9: 0.16700562 | AZ9: 0.06442577 | BC9: 江西一圈Phesgo 15ml | BD9: 21
C10: HSC | D10: 3444.49 | E10: =SUM(E23,E36) -> 355.434 | F10: =SUM(F23,F36) -> 169 | G10: =SUM(G23,G36) -> 187 | H10: =IFERROR(W10/V10,"") -> 0.47547505 | I10: =IFERROR(X10/V10,"") -> 0.52611736 | J10: =IFERROR(X10/W10,"") -> 1.1065089 | K10: =G10-F10 -> 18 | L10: =O10 -> 13 | M10: =IFERROR((X10+Y10)/V10,"") -> 0.56269236 | N10: =K10+L10 -> 31 | O10: =SUM(O23,O36) -> 13 | P10: =SUM(P23,P36) -> 0 | Q10: =IFERROR((X10+Z10)/V10,"") -> 0.52611736 | R10: =K10+P10 -> 18 | S10: =SUM(S23,S36) -> 0 | T10: =SUM(T23,T36) -> 0 | U10: =SUM(U23,U36) -> 0 | V10: =SUM(V23,V36) -> 1224288.9 | W10: =SUM(W23,W36) -> 582118.81 | X10: =SUM(X23,X36) -> 644119.63 | Y10: =SUM(Y23,Y36) -> 44778.37 | Z10: =SUM(Z23,Z36) -> 0 | AB10: 廖苏亮 | AC10: 0.71888898 | AD10: 0.82818581 | AE10: 0 | AF10: 0 | AG10: 0 | AH10: 0 | AI10: 0.76101608 | AJ10: 0 | AK10: 0 | AN10: 廖苏亮 | AO10: 1.1211728 | AP10: 0.22973616 | AQ10: 0.88710213 | AR10: 0.2532637 | AS10: 1.0269046 | AT10: 0.23905115 | AV10: 廖苏亮 | AW10: 1.1211728 | AX10: 0.44044944 | AY10: 0.22973616 | AZ10: 0.10337079 | BC10: 林丽贞Herceptin IV | BD10: 212
C11: PIV | D11: 3985.87 | E11: =SUM(E24,E37) -> 299.66752 | F11: =SUM(F24,F37) -> 176 | G11: =SUM(G24,G37) -> 156 | H11: =IFERROR(W11/V11,"") -> 0.58731757 | I11: =IFERROR(X11/V11,"") -> 0.52057694 | J11: =IFERROR(X11/W11,"") -> 0.88636364 | K11: =G11-F11 -> -20 | L11: =O11 -> 43 | M11: =IFERROR((X11+Y11)/V11,"") -> 0.6640693 | N11: =K11+L11 -> 23 | O11: =SUM(O24,O37) -> 43 | P11: =SUM(P24,P37) -> 0 | Q11: =IFERROR((X11+Z11)/V11,"") -> 0.52057694 | R11: =K11+P11 -> -20 | S11: =SUM(S24,S37) -> 0 | T11: =SUM(T24,T37) -> 0 | U11: =SUM(U24,U37) -> 0 | V11: =SUM(V24,V37) -> 1194435.8 | W11: =SUM(W24,W37) -> 701513.12 | X11: =SUM(X24,X37) -> 621795.72 | Y11: =SUM(Y24,Y37) -> 171392.41 | Z11: =SUM(Z24,Z37) -> 0 | AB11: 温若华 | AC11: 0.70307652 | AD11: 0.31344711 | AE11: 0 | AF11: 0 | AG11: 0 | AH11: 0 | AI11: 0.54918001 | AJ11: 0 | AK11: 0 | AN11: 温若华 | AO11: 1.0337013 | AP11: 0.22447964 | AQ11: 0.80635442 | AR11: 0.090866526 | AS11: 0.9296054 | AT11: 0.16859268 | AV11: 温若华 | AW11: 1.0337013 | AX11: 0.25817556 | AY11: 0.22447964 | AZ11: 0.065404475 | BC11: 林丽贞Herceptin SC | BD11: 97
C12: P-10ml | D12: 6232.07 | E12: =SUM(E25,E38) -> 548.50145 | F12: =SUM(F25,F38) -> 661.75908 | G12: =SUM(G25,G38) -> 564 | H12: =IFERROR(W12/V12,"") -> 1.2064856 | I12: =IFERROR(X12/V12,"") -> 1.0282562 | J12: =IFERROR(X12/W12,"") -> 0.85227391 | K12: =G12-F12 -> -97.759081 | L12: =O12 -> 150 | M12: =IFERROR((X12+Y12)/V12,"") -> 1.3017285 | N12: =K12+L12 -> 52.240919 | O12: =SUM(O25,O38) -> 150 | P12: =SUM(P25,P38) -> 0 | Q12: =IFERROR((X12+Z12)/V12,"") -> 1.0282562 | R12: =K12+P12 -> -97.759081 | S12: =SUM(S25,S38) -> 0 | T12: =SUM(T25,T38) -> 0 | U12: =SUM(U25,U38) -> 0 | V12: =SUM(V25,V38) -> 3418299.5 | W12: =SUM(W25,W38) -> 4124128.9 | X12: =SUM(X25,X38) -> 3514887.5 | Y12: =SUM(Y25,Y38) -> 934810.5 | Z12: =SUM(Z25,Z38) -> 0 | AB12: 张敏 | AC12: 0.88458196 | AD12: 0.0066351423 | AE12: 0 | AF12: 0 | AG12: 0 | AH12: 0 | AI12: 0.60580253 | AJ12: 0 | AK12: 0 | AN12: 张敏 | AO12: 1.4431278 | AP12: 0.28117598 | AQ12: 0.98260313 | AR12: 0.0019889566 | AS12: 1.2813735 | AT12: 0.18893926 | AV12: 张敏 | AW12: 1.4431278 | AX12: 0.52623211 | AY12: 0.28117598 | AZ12: 0.13672496 | BC12: 林丽贞Itovebi 3mg | BD12: 18
C13: P-15ml | D13: 8489.27 | E13: =SUM(E26,E39) -> 37.000042 | F13: =SUM(F26,F39) -> 38 | G13: =SUM(G26,G39) -> 33 | H13: =IFERROR(W13/V13,"") -> 1.0270258 | I13: =IFERROR(X13/V13,"") -> 0.89189087 | J13: =IFERROR(X13/W13,"") -> 0.86842105 | K13: =G13-F13 -> -5 | L13: =O13 -> 4 | M13: =IFERROR((X13+Y13)/V13,"") -> 0.99999885 | N13: =K13+L13 -> -1 | O13: =SUM(O26,O39) -> 4 | P13: =SUM(P26,P39) -> 0 | Q13: =IFERROR((X13+Z13)/V13,"") -> 0.89189087 | R13: =K13+P13 -> -5 | S13: =SUM(S26,S39) -> 0 | T13: =SUM(T26,T39) -> 0 | U13: =SUM(U26,U39) -> 0 | V13: =SUM(V26,V39) -> 314103.35 | W13: =SUM(W26,W39) -> 322592.26 | X13: =SUM(X26,X39) -> 280145.91 | Y13: =SUM(Y26,Y39) -> 33957.08 | Z13: =SUM(Z26,Z39) -> 0 | AB13: 林丽贞 | AC13: 0.67566688 | AD13: 0.94274425 | AE13: 0 | AF13: 0 | AG13: 0 | AH13: 0 | AI13: 0.78118477 | AJ13: 0 | AK13: 0 | AN13: 林丽贞 | AO13: 0.92232187 | AP13: 0.21555 | AQ13: 1.2127643 | AR13: 0.27667753 | AS13: 1.0563587 | AT13: 0.24092943 | AV13: 林丽贞 | AW13: 0.92232187 | AX13: 0.33670482 | AY13: 0.21555 | AZ13: 0.091030077 | BC13: 林丽贞Itovebi 9mg | BD13: 7
C14: I-3mg | D14: 3566.02 | E14: =SUM(E27,E40) -> 37.384708 | F14: =SUM(F27,F40) -> 6 | G14: =SUM(G27,G40) -> 11 | H14: =IFERROR(W14/V14,"") -> 0.16049343 | I14: =IFERROR(X14/V14,"") -> 0.29423796 | J14: =IFERROR(X14/W14,"") -> 1.8333333 | K14: =G14-F14 -> 5 | L14: =O14 -> 0 | M14: =IFERROR((X14+Y14)/V14,"") -> 0.29423796 | N14: =K14+L14 -> 5 | O14: =SUM(O27,O40) -> 0 | P14: =SUM(P27,P40) -> 0 | Q14: =IFERROR((X14+Z14)/V14,"") -> 0.29423796 | R14: =K14+P14 -> 5 | S14: =SUM(S27,S40) -> 0 | T14: =SUM(T27,T40) -> 0 | U14: =SUM(U27,U40) -> 0 | V14: =SUM(V27,V40) -> 133314.62 | W14: =SUM(W27,W40) -> 21396.12 | X14: =SUM(X27,X40) -> 39226.22 | Y14: =SUM(Y27,Y40) -> 0 | Z14: =SUM(Z27,Z40) -> 0 | AB14: 陈慧源 | AC14: 0.80572118 | AD14: 1.4738612 | AE14: 0 | AF14: 0 | AG14: 0 | AH14: 0 | AI14: 0.96452633 | AJ14: 0 | AK14: 0 | AN14: 陈慧源 | AO14: 1.1657366 | AP14: 0.25661997 | AQ14: 1.5375766 | AR14: 0.42568102 | AS14: 1.2778201 | AT14: 0.29987529 | AV14: 陈慧源 | AW14: 1.1657366 | AX14: 0.54227405 | AY14: 0.25661997 | AZ14: 0.1292517 | BC14: 林丽贞Perjeta | BD14: 295
C15: I-9mg | D15: 10698.05 | E15: =SUM(E28,E41) -> 0 | F15: =SUM(F28,F41) -> 25 | G15: =SUM(G28,G41) -> 21 | H15: =IFERROR(W15/V15,"") | I15: =IFERROR(X15/V15,"") | J15: =IFERROR(X15/W15,"") -> 0.84 | K15: =G15-F15 -> -4 | L15: =O15 -> 3 | M15: =IFERROR((X15+Y15)/V15,"") | N15: =K15+L15 -> -1 | O15: =SUM(O28,O41) -> 3 | P15: =SUM(P28,P41) -> 0 | Q15: =IFERROR((X15+Z15)/V15,"") | R15: =K15+P15 -> -4 | S15: =SUM(S28,S41) -> 0 | T15: =SUM(T28,T41) -> 0 | U15: =SUM(U28,U41) -> 0 | V15: =SUM(V28,V41) -> 0 | W15: =SUM(W28,W41) -> 267451.25 | X15: =SUM(X28,X41) -> 224659.05 | Y15: =SUM(Y28,Y41) -> 32094.15 | Z15: =SUM(Z28,Z41) -> 0 | AB15: 陈康乐 | AC15: 0.46170815 | AD15: 0.82721117 | AE15: 0 | AF15: 0 | AG15: 0 | AH15: 0 | AI15: 0.6368674 | AJ15: 0 | AK15: 0 | AN15: 陈康乐 | AO15: 0.80283226 | AP15: 0.14787291 | AQ15: 0.92539574 | AR15: 0.24509191 | AS15: 0.87537599 | AT15: 0.19635386 | AV15: 陈康乐 | AW15: 0.80283226 | AX15: 0.17835366 | AY15: 0.14787291 | AZ15: 0.050480769 | BC15: 林丽贞Phesgo 10ml | BD15: 321
B16: 江西一圈 | C16: 全产品 | H16: =IFERROR(W16/V16,"") -> 0.87978924 | I16: =IFERROR(X16/V16,"") -> 0.70029827 | J16: =IFERROR(X16/W16,"") -> 0.79598413 | K16: =(X16-W16)/10000 -> -70.907956 | L16: =Y16/10000 -> 84.632452 | M16: =IFERROR((X16+Y16)/V16,"") -> 0.91453037 | N16: =K16+L16 -> 13.724496 | P16: =Z16/10000 -> 0 | Q16: =IFERROR((X16+Z16)/V16,"") -> 0.70029827 | R16: =K16+P16 -> -70.907956 | V16: =SUM(V22:V28) -> 3950502.8 | W16: =SUM(W22:W28) -> 3475609.8 | X16: =SUM(X22:X28) -> 2766530.2 | Y16: =SUM(Y22:Y28) -> 846324.52 | Z16: =SUM(Z22:Z28) -> 0 | AB16: 李嘉妮 | AC16: 0.61076324 | AD16: 0.64091686 | AE16: 0 | AF16: 0 | AG16: 0 | AH16: 0 | AI16: 0.62152351 | AJ16: 0 | AK16: 0 | AN16: 李嘉妮 | AO16: 0.8169321 | AP16: 0.19466847 | AQ16: 1.1017978 | AR16: 0.18908621 | AS16: 0.93427303 | AT16: 0.19257637 | AV16: 李嘉妮 | AW16: 0.8169321 | AX16: 0.25710419 | AY16: 0.19466847 | AZ16: 0.074424899 | BC16: 林丽贞Phesgo 15ml | BD16: 27
C17: 策略 | H17: =IFERROR(W17/V17,"") -> 1.0324424 | I17: =IFERROR(X17/V17,"") -> 0.79494876 | J17: =IFERROR(X17/W17,"") -> 0.76996908 | K17: =(X17-W17)/10000 -> -61.876602 | L17: =Y17/10000 -> 76.477852 | M17: =IFERROR((X17+Y17)/V17,"") -> 1.0884847 | N17: =K17+L17 -> 14.60125 | P17: =Z17/10000 -> 0 | Q17: =IFERROR((X17+Z17)/V17,"") -> 0.79494876 | R17: =K17+P17 -> -61.876602 | V17: =SUM(V25:V28) -> 2605399.9 | W17: =SUM(W25:W28) -> 2689925.4 | X17: =SUM(X25:X28) -> 2071159.4 | Y17: =SUM(Y25:Y28) -> 764778.52 | Z17: =SUM(Z25:Z28) -> 0 | AB17: 刘晓萍 | AC17: 0.81280734 | AD17: 1.4738612 | AE17: 0 | AF17: 0 | AG17: 0 | AH17: 0 | AI17: 0.97263691 | AJ17: 0 | AK17: 0 | AN17: 刘晓萍 | AO17: 1.1801456 | AP17: 0.25882649 | AQ17: 1.5375766 | AR17: 0.42568103 | AS17: 1.2896076 | AT17: 0.30222913 | AV17: 刘晓萍 | AW17: 1.1801456 | AX17: 0.56965944 | AY17: 0.25882649 | AZ17: 0.13519092 | BC17: 周小英Herceptin IV | BD17: 268
C18: HF | E18: =SUM(E22:E23,E25:E26) -> 569.84045 | F18: =SUM(F22:F23,F25:F26) -> 516.75908 | G18: =SUM(G22:G23,G25:G26) -> 460 | H18: =IFERROR(W18/V18,"") -> 0.95431234 | I18: =IFERROR(X18/V18,"") -> 0.82149427 | J18: =IFERROR(X18/W18,"") -> 0.86082328 | K18: =G18-F18 -> -56.759081 | L18: =O18 -> 127 | M18: =IFERROR((X18+Y18)/V18,"") -> 1.0699381 | N18: =K18+L18 -> 70.240919 | O18: =SUM(O22:O23,O25:O26) -> 127 | P18: =SUM(P22:P23,P25:P26) -> 0 | Q18: =IFERROR((X18+Z18)/V18,"") -> 0.82149427 | R18: =K18+P18 -> -56.759081 | S18: =SUM(S22:S23,S25:S26) -> 0 | T18: =SUM(T22:T23,T25:T26) -> 0 | U18: =SUM(U22:U23,U25:U26) -> 0 | V18: =SUM(V22:V23,V25:V26) -> 3122791.8 | W18: =SUM(W22:W23,W25:W26) -> 2980118.8 | X18: =SUM(X22:X23,X25:X26) -> 2565355.6 | Y18: =SUM(Y22:Y23,Y25:Y26) -> 775838.42 | Z18: =SUM(Z22:Z23,Z25:Z26) -> 0 | AB18: 谢燕贞 | AC18: 1.1110415 | AD18: 1.646023 | AE18: 0 | AF18: 0 | AG18: 0 | AH18: 0 | AI18: 1.3315283 | AJ18: 0 | AK18: 0 | AN18: 谢燕贞 | AO18: 1.0837409 | AP18: 0.35617998 | AQ18: 1.917152 | AR18: 0.48861893 | AS18: 1.4795146 | AT18: 0.4132469 | AV18: 谢燕贞 | AW18: 1.0837409 | AX18: 0.53562654 | AY18: 0.35617998 | AZ18: 0.2014742 | BC18: 周小英Herceptin SC | BD18: 540
C19: PF | E19: =E24+E25+E26*2 -> 607.70439 | F19: =F24+F25+F26*2 -> 490.75908 | G19: =G24+G25+G26*2 -> 361 | H19: =IFERROR(W19/V19,"") -> 0.85688923 | I19: =IFERROR(X19/V19,"") -> 0.6429577 | J19: =IFERROR(X19/W19,"") -> 0.75033934 | K19: =G19-F19 -> -129.75908 | L19: =O19 -> 136 | M19: =IFERROR((X19+Y19)/V19,"") -> 0.89200191 | N19: =K19+L19 -> 6.2409188 | O19: =O24+O25+O26*2 -> 136 | P19: =P24+P25+P26*2 -> 0 | Q19: =IFERROR((X19+Z19)/V19,"") -> 0.6429577 | R19: =K19+P19 -> -129.75908 | S19: =S24+S25+S26*2 -> 0 | T19: =T24+T25+T26*2 -> 0 | U19: =U24+U25+U26*2 -> 0 | V19: =SUM(V24:V26) -> 3267968 | W19: =SUM(W24:W26) -> 2800286.6 | X19: =SUM(X24:X26) -> 2101165.2 | Y19: =SUM(Y24:Y26) -> 813868.52 | Z19: =SUM(Z24:Z26) -> 0 | AB19: 张慧卿 | AC19: 0.41611273 | AD19: 0.26219702 | AE19: 0 | AF19: 0 | AG19: 0 | AH19: 0 | AI19: 0.35664839 | AJ19: 0 | AK19: 0 | AN19: 张慧卿 | AO19: 0.5466867 | AP19: 0.13274458 | AQ19: 0.9096615 | AR19: 0.077721022 | AS19: 0.70334318 | AT19: 0.11052091 | AV19: 张慧卿 | AW19: 0.5466867 | AX19: 0.30913349 | AY19: 0.13274458 | AZ19: 0.088992974 | BC19: 周小英Itovebi 3mg | BD19: 18
C20: P-折算10ml | E20: =E25+E26*2 -> 420.75912 | F20: =F25+F26*2 -> 414.75908 | G20: =G25+G26*2 -> 332 | H20: =IFERROR(W20/V20,"") -> 0.98990499 | I20: =IFERROR(X20/V20,"") -> 0.78704319 | J20: =IFERROR(X20/W20,"") -> 0.79506943 | K20: =G20-F20 -> -82.759081 | L20: =O20 -> 121 | M20: =IFERROR((X20+Y20)/V20,"") -> 1.085946 | N20: =K20+L20 -> 38.240919 | O20: =O25+O26*2 -> 121 | P20: =P25+P26*2 -> 0 | Q20: =IFERROR((X20+Z20)/V20,"") -> 0.78704319 | R20: =K20+P20 -> -82.759081 | S20: =S25+S26*2 -> 0 | T20: =T25+T26*2 -> 0 | U20: =U25+U26*2 -> 0 | V20: =SUM(V25:V26) -> 2522828.5 | W20: =SUM(W25:W26) -> 2497360.5 | X20: =SUM(X25:X26) -> 1985575 | Y20: =SUM(Y25:Y26) -> 754080.47 | Z20: =SUM(Z25:Z26) -> 0 | AB20: 郑长洋 | AC20: 0.30034239 | AD20: 0.8390079 | AE20: 0 | AF20: 0 | AG20: 0 | AH20: 0 | AI20: 0.65054786 | AJ20: 0 | AK20: 0 | AN20: 郑长洋 | AO20: 0.65955705 | AP20: 0.095555097 | AQ20: 0.98532247 | AR20: 0.24392401 | AS20: 0.90061908 | AT20: 0.19501449 | AV20: 郑长洋 | AW20: 0.65955705 | AX20: 0.10018904 | AY20: 0.095555097 | AZ20: 0.018205462 | BC20: 周小英Itovebi 9mg | BD20: 34
C21: I-折算9mg | E21: =E27/3+E28 -> 7.7183522 | F21: =F27/3+F28 -> 18 | G21: =G27/3+G28 -> 8 | H21: =IFERROR(W21/V21,"") -> 2.3321021 | I21: =IFERROR(X21/V21,"") -> 1.0364899 | J21: =IFERROR(X21/W21,"") -> 0.4444445 | K21: =G21-F21 -> -10 | L21: =O21 -> 1 | M21: =IFERROR((X21+Y21)/V21,"") -> 1.1660512 | N21: =K21+L21 -> -9 | O21: =O27/3+O28 -> 1 | P21: =P27/3+P28 -> 0 | Q21: =IFERROR((X21+Z21)/V21,"") -> 1.0364899 | R21: =K21+P21 -> -10 | S21: =S27/3+S28 -> 0 | T21: =T27/3+T28 -> 0 | U21: =U27/3+U28 -> 0 | V21: =SUM(V27:V28) -> 82571.395 | W21: =SUM(W27:W28) -> 192564.92 | X21: =SUM(X27:X28) -> 85584.42 | Y21: =SUM(Y27:Y28) -> 10698.05 | Z21: =SUM(Z27:Z28) -> 0 | AB21: 唐晓玉 | AC21: 1.4234711 | AD21: 0.60648921 | AE21: 0 | AF21: 0 | AG21: 0 | AH21: 0 | AI21: 0.97281668 | AJ21: 0 | AK21: 0 | AN21: 唐晓玉 | AO21: 1.650805 | AP21: 0.45346963 | AQ21: 0.58765457 | AR21: 0.18035253 | AS21: 0.9873159 | AT21: 0.2981833 | AV21: 唐晓玉 | AW21: 1.650805 | AX21: 0.33409524 | AY21: 0.45346963 | AZ21: 0.10095238 | BC21: 周小英Perjeta | BD21: 488
A22: 江西一圈Herceptin IV | C22: HIV | D22: 4535.5 | E22: 0.31336976 | F22: 51 | G22: =_xlfn.XLOOKUP(A22,BC:BC,BD:BD,0) -> 61 | H22: =IFERROR(W22/V22,"") -> 162.74704 | I22: =IFERROR(X22/V22,"") -> 194.65822 | J22: =IFERROR(X22/W22,"") -> 1.1960784 | K22: =G22-F22 -> 10 | L22: =O22 -> 1 | M22: =IFERROR((X22+Y22)/V22,"") -> 197.84934 | N22: =K22+L22 -> 11 | O22: 1 | P22: =SUM(S22:U22) -> 0 | Q22: =IFERROR((X22+Z22)/V22,"") -> 194.65822 | R22: =K22+P22 -> 10 | V22: =E22*D22 -> 1421.2885 | W22: =F22*D22 -> 231310.5 | X22: =G22*D22 -> 276665.5 | Y22: =L22*D22 -> 4535.5 | Z22: =P22*D22 -> 0 | AB22: (空缺) | AC22: 1.1367677 | AD22: 0.42877044 | AE22: 0 | AF22: 0 | AG22: 0 | AH22: 0 | AI22: 0.49591716 | AJ22: 0 | AK22: 0 | AN22: (空缺) | AO22: 2.2599443 | AP22: 0.35990368 | AQ22: 0.40204216 | AR22: 0.13329198 | AS22: 0.55485078 | AT22: 0.15443108 | AV22: (空缺) | AW22: 2.2599443 | AX22: 0.11377246 | AY22: 0.35990368 | AZ22: 0.020958084 | BC22: 周小英Phesgo 10ml | BD22: 450
A23: 江西一圈Herceptin SC | C23: HSC | D23: 3444.49 | E23: 173.76797 | F23: 73 | G23: =_xlfn.XLOOKUP(A23,BC:BC,BD:BD,0) -> 88 | H23: =IFERROR(W23/V23,"") -> 0.42010043 | I23: =IFERROR(X23/V23,"") -> 0.50642243 | J23: =IFERROR(X23/W23,"") -> 1.2054795 | K23: =G23-F23 -> 15 | L23: =O23 -> 5 | M23: =IFERROR((X23+Y23)/V23,"") -> 0.53519643 | N23: =K23+L23 -> 20 | O23: 5 | P23: =SUM(S23:U23) -> 0 | Q23: =IFERROR((X23+Z23)/V23,"") -> 0.50642243 | R23: =K23+P23 -> 15 | V23: =E23*D23 -> 598542.05 | W23: =F23*D23 -> 251447.77 | X23: =G23*D23 -> 303115.12 | Y23: =L23*D23 -> 17222.45 | Z23: =P23*D23 -> 0 | AB23: 高艳 | AC23: 2.4244558 | AD23: 0.47154544 | AE23: 0 | AF23: 0 | AG23: 0 | AH23: 0 | AI23: 1.1429363 | AJ23: 0 | AK23: 0 | AN23: 高艳 | AO23: 2.349551 | AP23: 0.76891454 | AQ23: 0.49025876 | AR23: 0.13823363 | AS23: 0.97557547 | AT23: 0.34400121 | AV23: 高艳 | AW23: 2.349551 | AX23: 0.37042182 | AY23: 0.76891454 | AZ23: 0.13351711 | BC23: 周小英Phesgo 15ml | BD23: 14
A24: 江西一圈Perjeta | C24: PIV | D24: 3985.87 | E24: 186.94527 | F24: 76 | G24: =_xlfn.XLOOKUP(A24,BC:BC,BD:BD,0) -> 29 | H24: =IFERROR(W24/V24,"") -> 0.40653609 | I24: =IFERROR(X24/V24,"") -> 0.15512562 | J24: =IFERROR(X24/W24,"") -> 0.38157895 | K24: =G24-F24 -> -47 | L24: =O24 -> 15 | M24: =IFERROR((X24+Y24)/V24,"") -> 0.235363 | N24: =K24+L24 -> -32 | O24: 15 | P24: =SUM(S24:U24) -> 0 | Q24: =IFERROR((X24+Z24)/V24,"") -> 0.15512562 | R24: =K24+P24 -> -47 | V24: =E24*D24 -> 745139.54 | W24: =F24*D24 -> 302926.12 | X24: =G24*D24 -> 115590.23 | Y24: =L24*D24 -> 59788.05 | Z24: =P24*D24 -> 0 | AB24: 吕杨 | AC24: 0.82274344 | AD24: 1.4718605 | AE24: 0 | AF24: 0 | AG24: 0 | AH24: 0 | AI24: 0.92790864 | AJ24: 0 | AK24: 0 | AN24: 吕杨 | AO24: 1.1223574 | AP24: 0.2643055 | AQ24: 1.7347595 | AR24: 0.42567269 | AS24: 1.2475765 | AT24: 0.29283345 | AV24: 吕杨 | AW24: 1.1223574 | AX24: 0.65091864 | AY24: 0.2643055 | AZ24: 0.167979 | BC24: 唐晓玉Herceptin IV | BD24: 67
A25: 江西一圈Phesgo 10ml | C25: P-10ml | D25: 6232.07 | E25: 370.75908 | F25: 370.75908 | G25: =_xlfn.XLOOKUP(A25,BC:BC,BD:BD,0) -> 290 | H25: =IFERROR(W25/V25,"") -> 1 | I25: =IFERROR(X25/V25,"") -> 0.78217909 | J25: =IFERROR(X25/W25,"") -> 0.78217909 | K25: =G25-F25 -> -80.759081 | L25: =O25 -> 121 | M25: =IFERROR((X25+Y25)/V25,"") -> 1.1085366 | N25: =K25+L25 -> 40.240919 | O25: =78+43 -> 121 | P25: =SUM(S25:U25) -> 0 | Q25: =IFERROR((X25+Z25)/V25,"") -> 0.78217909 | R25: =K25+P25 -> -80.759081 | V25: =E25*D25 -> 2310596.5 | W25: =F25*D25 -> 2310596.5 | X25: =G25*D25 -> 1807300.3 | Y25: =L25*D25 -> 754080.47 | Z25: =P25*D25 -> 0 | AB25: 梅海波 | AC25: 1.8015984 | AD25: 0.6818665 | AE25: 0 | AF25: 0 | AG25: 0 | AH25: 0 | AI25: 1.1499518 | AJ25: 0 | AK25: 0 | AN25: 梅海波 | AO25: 1.9534534 | AP25: 0.5699143 | AQ25: 0.61283829 | AR25: 0.1997922 | AS25: 1.0607777 | AT25: 0.3476635 | AV25: 梅海波 | AW25: 1.9534534 | AX25: 0.29212945 | AY25: 0.5699143 | AZ25: 0.095664901 | BC25: 唐晓玉Herceptin SC | BD25: 99
A26: 江西一圈Phesgo 15ml | C26: P-15ml | D26: 8489.27 | E26: 25.000021 | F26: 22 | G26: =_xlfn.XLOOKUP(A26,BC:BC,BD:BD,0) -> 21 | H26: =IFERROR(W26/V26,"") -> 0.87999925 | I26: =IFERROR(X26/V26,"") -> 0.83999929 | J26: =IFERROR(X26/W26,"") -> 0.95454545 | K26: =G26-F26 -> -1 | L26: =O26 -> 0 | M26: =IFERROR((X26+Y26)/V26,"") -> 0.83999929 | N26: =K26+L26 -> -1 | P26: =SUM(S26:U26) -> 0 | Q26: =IFERROR((X26+Z26)/V26,"") -> 0.83999929 | R26: =K26+P26 -> -1 | V26: =E26*D26 -> 212231.93 | W26: =F26*D26 -> 186763.94 | X26: =G26*D26 -> 178274.67 | Y26: =L26*D26 -> 0 | Z26: =P26*D26 -> 0 | AB26: 王颖婷 | AC26: 2.1508514 | AD26: 0.57056185 | AE26: 0 | AF26: 0 | AG26: 0 | AH26: 0 | AI26: 1.1083447 | AJ26: 0 | AK26: 0 | AN26: 王颖婷 | AO26: 2.3147854 | AP26: 0.67890507 | AQ26: 0.53225279 | AR26: 0.16812116 | AS26: 1.0121211 | AT26: 0.33414387 | AV26: 王颖婷 | AW26: 2.3147854 | AX26: 0.24948279 | AY26: 0.67890507 | AZ26: 0.082842643 | BC26: 唐晓玉Itovebi 3mg | BD26: 5
A27: 江西一圈Itovebi 3mg | C27: I-3mg | D27: 3566.02 | E27: 23.155056 | F27: 6 | G27: =_xlfn.XLOOKUP(A27,BC:BC,BD:BD,0) -> 6 | H27: =IFERROR(W27/V27,"") -> 0.25912267 | I27: =IFERROR(X27/V27,"") -> 0.25912267 | J27: =IFERROR(X27/W27,"") -> 1 | K27: =G27-F27 -> 0 | L27: =O27 -> 0 | M27: =IFERROR((X27+Y27)/V27,"") -> 0.25912267 | N27: =K27+L27 -> 0 | P27: =SUM(S27:U27) -> 0 | Q27: =IFERROR((X27+Z27)/V27,"") -> 0.25912267 | R27: =K27+P27 -> 0 | V27: =E27*D27 -> 82571.395 | W27: =F27*D27 -> 21396.12 | X27: =G27*D27 -> 21396.12 | Y27: =L27*D27 -> 0 | Z27: =P27*D27 -> 0 | AB27: 张霞云 | AC27: 1.2929984 | AD27: 0.66362338 | AE27: 0 | AF27: 0 | AG27: 0 | AH27: 0 | AI27: 0.97727852 | AJ27: 0 | AK27: 0 | AN27: 张霞云 | AO27: 1.5495771 | AP27: 0.41112721 | AQ27: 0.54886651 | AR27: 0.19540551 | AS27: 0.9672557 | AT27: 0.2987721 | AV27: 张霞云 | AW27: 1.5495771 | AX27: 0.34977324 | AY27: 0.41112721 | AZ27: 0.10204082 | BC27: 唐晓玉Itovebi 9mg | BD27: 15
A28: 江西一圈Itovebi 9mg | C28: I-9mg | D28: 10698.05 | E28: 0 | F28: 16 | G28: =_xlfn.XLOOKUP(A28,BC:BC,BD:BD,0) -> 6 | H28: =IFERROR(W28/V28,"") | I28: =IFERROR(X28/V28,"") | J28: =IFERROR(X28/W28,"") -> 0.375 | K28: =G28-F28 -> -10 | L28: =O28 -> 1 | M28: =IFERROR((X28+Y28)/V28,"") | N28: =K28+L28 -> -9 | O28: 1 | P28: =SUM(S28:U28) -> 0 | Q28: =IFERROR((X28+Z28)/V28,"") | R28: =K28+P28 -> -10 | V28: =E28*D28 -> 0 | W28: =F28*D28 -> 171168.8 | X28: =G28*D28 -> 64188.3 | Y28: =L28*D28 -> 10698.05 | Z28: =P28*D28 -> 0 | AB28: 许辉容 | AC28: 0.51706877 | AD28: 0.95359211 | AE28: 0 | AF28: 0 | AG28: 0 | AH28: 0 | AI28: 0.72516954 | AJ28: 0 | AK28: 0 | AN28: 许辉容 | AO28: 0.85878731 | AP28: 0.16492641 | AQ28: 0.81968304 | AR28: 0.28500973 | AS28: 0.83748558 | AT28: 0.22412338 | AV28: 许辉容 | AW28: 0.85878731 | AX28: 0.34956347 | AY28: 0.16492641 | AZ28: 0.081598388 | BC28: 唐晓玉Perjeta | BD28: 127
B29: 唐晓玉 | C29: 全产品 | H29: =IFERROR(W29/V29,"") -> 1.0727663 | I29: =IFERROR(X29/V29,"") -> 1.1167278 | J29: =IFERROR(X29/W29,"") -> 1.0409796 | K29: =(X29-W29)/10000 -> 12.356509 | L29: =Y29/10000 -> 37.524349 | M29: =IFERROR((X29+Y29)/V29,"") -> 1.2502306 | N29: =K29+L29 -> 49.880858 | P29: =Z29/10000 -> 0 | Q29: =IFERROR((X29+Z29)/V29,"") -> 1.1167278 | R29: =K29+P29 -> 12.356509 | V29: =SUM(V35:V41) -> 2810754.5 | W29: =SUM(W35:W41) -> 3015282.7 | X29: =SUM(X35:X41) -> 3138847.8 | Y29: =SUM(Y35:Y41) -> 375243.49 | Z29: =SUM(Z35:Z41) -> 0 | AB29: (空缺) | AC29: 0.49443533 | AD29: #DIV/0! | AE29: 0 | AF29: #DIV/0! | AG29: 0 | AH29: #DIV/0! | AI29: 0.49443533 | AJ29: 0 | AK29: 0 | AN29: (空缺) | AO29: 4.6016139 | AP29: 0.13135992 | AQ29: #DIV/0! | AR29: #DIV/0! | AS29: 4.6016139 | AT29: 0.13135992 | AV29: (空缺) | AW29: 4.6016139 | AX29: #DIV/0! | AY29: 0.13135992 | AZ29: #DIV/0! | BC29: 唐晓玉Phesgo 10ml | BD29: 274
C30: 策略 | H30: =IFERROR(W30/V30,"") -> 1.6231172 | I30: =IFERROR(X30/V30,"") -> 1.5771892 | J30: =IFERROR(X30/W30,"") -> 0.97170383 | K30: =(X30-W30)/10000 -> -5.788387 | L30: =Y30/10000 -> 23.608321 | M30: =IFERROR((X30+Y30)/V30,"") -> 1.7645097 | N30: =K30+L30 -> 17.819934 | P30: =Z30/10000 -> 0 | Q30: =IFERROR((X30+Z30)/V30,"") -> 1.5771892 | R30: =K30+P30 -> -5.788387 | V30: =SUM(V38:V41) -> 1260317.5 | W30: =SUM(W38:W41) -> 2045643.1 | X30: =SUM(X38:X41) -> 1987759.3 | Y30: =SUM(Y38:Y41) -> 236083.21 | Z30: =SUM(Z38:Z41) -> 0 | AB30: 甘燕梅 | AC30: 0.45606654 | AD30: 0.39751827 | AE30: 0 | AF30: 0 | AG30: 0 | AH30: 0 | AI30: 0.43547632 | AJ30: 0 | AK30: 0 | AN30: 甘燕梅 | AO30: 0.7821225 | AP30: 0.1465063 | AQ30: 0.60954427 | AR30: 0.12505898 | AS30: 0.72187627 | AT30: 0.13886128 | AV30: 甘燕梅 | AW30: 0.7821225 | AX30: 0.42230576 | AY30: 0.1465063 | AZ30: 0.10025063 | BC30: 唐晓玉Phesgo 15ml | BD30: 12
C31: HF | E31: =SUM(E35:E36,E38:E39) -> 476.22463 | F31: =SUM(F35:F36,F38:F39) -> 456 | G31: =SUM(G35:G36,G38:G39) -> 452 | H31: =IFERROR(W31/V31,"") -> 1.0907503 | I31: =IFERROR(X31/V31,"") -> 1.0621567 | J31: =IFERROR(X31/W31,"") -> 0.97378533 | K31: =G31-F31 -> -4 | L31: =O31 -> 41 | M31: =IFERROR((X31+Y31)/V31,"") -> 1.1669913 | N31: =K31+L31 -> 37 | O31: =SUM(O35:O36,O38:O39) -> 41 | P31: =SUM(P35:P36,P38:P39) -> 0 | Q31: =IFERROR((X31+Z31)/V31,"") -> 1.0621567 | R31: =K31+P31 -> -4 | S31: =SUM(S35:S36,S38:S39) -> 0 | T31: =SUM(T35:T36,T38:T39) -> 0 | U31: =SUM(U35:U36,U38:U39) -> 0 | V31: =SUM(V35:V36,V38:V39) -> 2310715 | W31: =SUM(W35:W36,W38:W39) -> 2520413.2 | X31: =SUM(X35:X36,X38:X39) -> 2454341.4 | Y31: =SUM(Y35:Y36,Y38:Y39) -> 242243.03 | Z31: =SUM(Z35:Z36,Z38:Z39) -> 0 | AB31: 林露 | AC31: 0.3617315 | AD31: 1.9612992 | AE31: 0 | AF31: 0 | AG31: 0 | AH31: 0 | AI31: 1.7417199 | AJ31: 0 | AK31: 0 | AN31: 林露 | AO31: 1.3502782 | AP31: 0.11518451 | AQ31: 1.0941522 | AR31: 0.57088818 | AS31: 1.1182333 | AT31: 0.51302242 | AV31: 林露 | AW31: 1.3502782 | AX31: 0.15631692 | AY31: 0.11518451 | AZ31: 0.010706638 | BC31: 许辉容Herceptin IV | BD31: 301
C32: PF | E32: =E37+E38+E39*2 -> 314.46466 | F32: =F37+F38+F39*2 -> 423 | G32: =G37+G38+G39*2 -> 425 | H32: =IFERROR(W32/V32,"") -> 1.4153893 | I32: =IFERROR(X32/V32,"") -> 1.395928 | J32: =IFERROR(X32/W32,"") -> 0.98625021 | K32: =G32-F32 -> 2 | L32: =O32 -> 65 | M32: =IFERROR((X32+Y32)/V32,"") -> 1.592623 | N32: =K32+L32 -> 67 | O32: =O37+O38+O39*2 -> 65 | P32: =P37+P38+P39*2 -> 0 | Q32: =IFERROR((X32+Z32)/V32,"") -> 1.395928 | R32: =K32+P32 -> 2 | S32: =S37+S38+S39*2 -> 0 | T32: =T37+T38+T39*2 -> 0 | U32: =U37+U38+U39*2 -> 0 | V32: =SUM(V37:V39) -> 1658870.6 | W32: =SUM(W37:W39) -> 2347947.7 | X32: =SUM(X37:X39) -> 2315663.9 | Y32: =SUM(Y37:Y39) -> 326291.47 | Z32: =SUM(Z37:Z39) -> 0 | AB32: 林月榕 | AC32: 0.70797215 | AD32: 1.0617701 | AE32: 0 | AF32: 0 | AG32: 0 | AH32: 0 | AI32: 0.86220159 | AJ32: 0 | AK32: 0 | AN32: 林月榕 | AO32: 0.84962833 | AP32: 0.22572741 | AQ32: 1.1503644 | AR32: 0.30843808 | AS32: 1.0106302 | AT32: 0.26368643 | AV32: 林月榕 | AW32: 0.84962833 | AX32: 0.41370558 | AY32: 0.22572741 | AZ32: 0.11928934 | BC32: 许辉容Herceptin SC | BD32: 146
C33: P-折算10ml | E33: =E38+E39*2 -> 201.74241 | F33: =F38+F39*2 -> 323 | G33: =G38+G39*2 -> 298 | H33: =IFERROR(W33/V33,"") -> 1.6116088 | I33: =IFERROR(X33/V33,"") -> 1.4959464 | J33: =IFERROR(X33/W33,"") -> 0.92823172 | K33: =G33-F33 -> -25 | L33: =O33 -> 37 | M33: =IFERROR((X33+Y33)/V33,"") -> 1.6734363 | N33: =K33+L33 -> 12 | O33: =O38+O39*2 -> 37 | P33: =P38+P39*2 -> 0 | Q33: =IFERROR((X33+Z33)/V33,"") -> 1.4959464 | R33: =K33+P33 -> -25 | S33: =S38+S39*2 -> 0 | T33: =T38+T39*2 -> 0 | U33: =U38+U39*2 -> 0 | V33: =SUM(V38:V39) -> 1209574.3 | W33: =SUM(W38:W39) -> 1949360.7 | X33: =SUM(X38:X39) -> 1809458.4 | Y33: =SUM(Y38:Y39) -> 214687.11 | Z33: =SUM(Z38:Z39) -> 0 | AB33: 宋超平 | AC33: 0.45740838 | AD33: 0.47979913 | AE33: 0 | AF33: 0 | AG33: 0 | AH33: 0 | AI33: 0.46823738 | AJ33: 0 | AK33: 0 | AN33: 宋超平 | AO33: 1.0477557 | AP33: 0.14488652 | AQ33: 0.80459297 | AR33: 0.14249708 | AS33: 0.91624459 | AT33: 0.14369243 | AV33: 宋超平 | AW33: 1.0477557 | AX33: 0.33164983 | AY33: 0.14488652 | AZ33: 0.052188552 | BC33: 许辉容Itovebi 3mg | BD33: 10
C34: I-折算9mg | E34: =E40/3+E41 -> 4.7432171 | F34: =F40/3+F41 -> 9 | G34: =G40/3+G41 -> 16.666667 | H34: =IFERROR(W34/V34,"") -> 1.8974446 | I34: =IFERROR(X34/V34,"") -> 3.5137866 | J34: =IFERROR(X34/W34,"") -> 1.851852 | K34: =G34-F34 -> 7.6666667 | L34: =O34 -> 2 | M34: =IFERROR((X34+Y34)/V34,"") -> 3.935441 | N34: =K34+L34 -> 9.6666667 | O34: =O40/3+O41 -> 2 | P34: =P40/3+P41 -> 0 | Q34: =IFERROR((X34+Z34)/V34,"") -> 3.5137866 | R34: =K34+P34 -> 7.6666667 | S34: =S40/3+S41 -> 0 | T34: =T40/3+T41 -> 0 | U34: =U40/3+U41 -> 0 | V34: =SUM(V40:V41) -> 50743.221 | W34: =SUM(W40:W41) -> 96282.45 | X34: =SUM(X40:X41) -> 178300.85 | Y34: =SUM(Y40:Y41) -> 21396.1 | Z34: =SUM(Z40:Z41) -> 0 | AB34: 吴平辉 | AC34: 0.54384314 | AD34: 0.54045795 | AE34: 0 | AF34: 0 | AG34: 0 | AH34: 0 | AI34: 0.54241236 | AJ34: 0 | AK34: 0 | AN34: 吴平辉 | AO34: 0.65373684 | AP34: 0.17470906 | AQ34: 0.41861589 | AR34: 0.16267844 | AS34: 0.54033297 | AT34: 0.1694322 | AV34: 吴平辉 | AW34: 0.65373684 | AX34: 0.3737931 | AY34: 0.17470906 | AZ34: 0.11034483 | BC34: 许辉容Itovebi 9mg | BD34: 3
A35: 唐晓玉Herceptin IV | C35: HIV | D35: 4535.5 | E35: 104.8162 | F35: 53 | G35: =_xlfn.XLOOKUP(A35,BC:BC,BD:BD,0) -> 67 | H35: =IFERROR(W35/V35,"") -> 0.50564701 | I35: =IFERROR(X35/V35,"") -> 0.63921415 | J35: =IFERROR(X35/W35,"") -> 1.2641509 | K35: =G35-F35 -> 14 | L35: =O35 -> 0 | M35: =IFERROR((X35+Y35)/V35,"") -> 0.63921415 | N35: =K35+L35 -> 14 | P35: =SUM(S35:U35) -> 0 | Q35: =IFERROR((X35+Z35)/V35,"") -> 0.63921415 | R35: =K35+P35 -> 14 | V35: =E35*D35 -> 475393.89 | W35: =F35*D35 -> 240381.5 | X35: =G35*D35 -> 303878.5 | Y35: =L35*D35 -> 0 | Z35: =P35*D35 -> 0 | AB35: 钟明珠 | AC35: 0.79896544 | AD35: 0.80918591 | AE35: 0 | AF35: 0 | AG35: 0 | AH35: 0 | AI35: 0.80318695 | AJ35: 0 | AK35: 0 | AN35: 钟明珠 | AO35: 1.0847771 | AP35: 0.25186551 | AQ35: 0.87848221 | AR35: 0.239465 | AS35: 0.98167734 | AT35: 0.24655256 | AV35: 钟明珠 | AW35: 1.0847771 | AX35: 0.63282863 | AY35: 0.25186551 | AZ35: 0.16207846 | BC35: 许辉容Perjeta | BD35: 182
A36: 唐晓玉Herceptin SC | C36: HSC | D36: 3444.49 | E36: 181.66603 | F36: 96 | G36: =_xlfn.XLOOKUP(A36,BC:BC,BD:BD,0) -> 99 | H36: =IFERROR(W36/V36,"") -> 0.52844222 | I36: =IFERROR(X36/V36,"") -> 0.54495604 | J36: =IFERROR(X36/W36,"") -> 1.03125 | K36: =G36-F36 -> 3 | L36: =O36 -> 8 | M36: =IFERROR((X36+Y36)/V36,"") -> 0.58899289 | N36: =K36+L36 -> 11 | O36: 8 | P36: =SUM(S36:U36) -> 0 | Q36: =IFERROR((X36+Z36)/V36,"") -> 0.54495604 | R36: =K36+P36 -> 3 | V36: =E36*D36 -> 625746.82 | W36: =F36*D36 -> 330671.04 | X36: =G36*D36 -> 341004.51 | Y36: =L36*D36 -> 27555.92 | Z36: =P36*D36 -> 0 | AB36: 贾静 | AC36: 0.73169977 | AD36: 0.53602193 | AE36: 0 | AF36: 0 | AG36: 0 | AH36: 0 | AI36: 0.6574435 | AJ36: 0 | AK36: 0 | AN36: 贾静 | AO36: 0.96122967 | AP36: 0.2309031 | AQ36: 0.57252006 | AR36: 0.16074836 | AS36: 0.78890762 | AT36: 0.20343371 | AV36: 贾静 | AW36: 0.96122967 | AX36: 0.68450704 | AY36: 0.2309031 | AZ36: 0.2 | BC36: 许辉容Phesgo 10ml | BD36: 215
A37: 唐晓玉Perjeta | C37: PIV | D37: 3985.87 | E37: 112.72225 | F37: 100 | G37: =_xlfn.XLOOKUP(A37,BC:BC,BD:BD,0) -> 127 | H37: =IFERROR(W37/V37,"") -> 0.88713632 | I37: =IFERROR(X37/V37,"") -> 1.1266631 | J37: =IFERROR(X37/W37,"") -> 1.27 | K37: =G37-F37 -> 27 | L37: =O37 -> 28 | M37: =IFERROR((X37+Y37)/V37,"") -> 1.3750613 | N37: =K37+L37 -> 55 | O37: 28 | P37: =SUM(S37:U37) -> 0 | Q37: =IFERROR((X37+Z37)/V37,"") -> 1.1266631 | R37: =K37+P37 -> 27 | V37: =E37*D37 -> 449296.23 | W37: =F37*D37 -> 398587 | X37: =G37*D37 -> 506205.49 | Y37: =L37*D37 -> 111604.36 | Z37: =P37*D37 -> 0 | AB37: 李巍 | AC37: 0.90600332 | AD37: 1.376424 | AE37: 0 | AF37: 0 | AG37: 0 | AH37: 0 | AI37: 1.0642742 | AJ37: 0 | AK37: 0 | AN37: 李巍 | AO37: 1.4510118 | AP37: 0.28601164 | AQ37: 1.0031042 | AR37: 0.4006308 | AS37: 1.249839 | AT37: 0.32667915 | AV37: 李巍 | AW37: 1.4510118 | AX37: 0.88771267 | AY37: 0.28601164 | AZ37: 0.2 | BC37: 许辉容Phesgo 15ml | BD37: 17
A38: 唐晓玉Phesgo 10ml | C38: P-10ml | D38: 6232.07 | E38: 177.74237 | F38: 291 | G38: =_xlfn.XLOOKUP(A38,BC:BC,BD:BD,0) -> 274 | H38: =IFERROR(W38/V38,"") -> 1.6372011 | I38: =IFERROR(X38/V38,"") -> 1.541557 | J38: =IFERROR(X38/W38,"") -> 0.94158076 | K38: =G38-F38 -> -17 | L38: =O38 -> 29 | M38: =IFERROR((X38+Y38)/V38,"") -> 1.7047145 | N38: =K38+L38 -> 12 | O38: 29 | P38: =SUM(S38:U38) -> 0 | Q38: =IFERROR((X38+Z38)/V38,"") -> 1.541557 | R38: =K38+P38 -> -17 | V38: =E38*D38 -> 1107702.9 | W38: =F38*D38 -> 1813532.4 | X38: =G38*D38 -> 1707587.2 | Y38: =L38*D38 -> 180730.03 | Z38: =P38*D38 -> 0 | AB38: 王冲 | AC38: 0.59442669 | AD38: 0.75520003 | AE38: 0 | AF38: 0 | AG38: 0 | AH38: 0 | AI38: 0.68438068 | AJ38: 0 | AK38: 0 | AN38: 王冲 | AO38: 0.99780231 | AP38: 0.18598097 | AQ38: 0.99479493 | AR38: 0.22126314 | AS38: 0.99583332 | AT38: 0.2062903 | AV38: 王冲 | AW38: 0.99780231 | AX38: 0.40308219 | AY38: 0.18598097 | AZ38: 0.097945205 | BC38: 钟明珠Herceptin IV | BD38: 219
A39: 唐晓玉Phesgo 15ml | C39: P-15ml | D39: 8489.27 | E39: 12.000021 | F39: 16 | G39: =_xlfn.XLOOKUP(A39,BC:BC,BD:BD,0) -> 12 | H39: =IFERROR(W39/V39,"") -> 1.333331 | I39: =IFERROR(X39/V39,"") -> 0.99999823 | J39: =IFERROR(X39/W39,"") -> 0.75 | K39: =G39-F39 -> -4 | L39: =O39 -> 4 | M39: =IFERROR((X39+Y39)/V39,"") -> 1.333331 | N39: =K39+L39 -> 0 | O39: 4 | P39: =SUM(S39:U39) -> 0 | Q39: =IFERROR((X39+Z39)/V39,"") -> 0.99999823 | R39: =K39+P39 -> -4 | V39: =E39*D39 -> 101871.42 | W39: =F39*D39 -> 135828.32 | X39: =G39*D39 -> 101871.24 | Y39: =L39*D39 -> 33957.08 | Z39: =P39*D39 -> 0 | AB39: 王稼辉 | AC39: 0.83836349 | AD39: 1.1683466 | AE39: 0 | AF39: 0 | AG39: 0 | AH39: 0 | AI39: 0.96824288 | AJ39: 0 | AK39: 0 | AN39: 王稼辉 | AO39: 1.1359531 | AP39: 0.26590478 | AQ39: 0.79985809 | AR39: 0.34800358 | AS39: 0.97712018 | AT39: 0.2994572 | AV39: 王稼辉 | AW39: 1.1359531 | AX39: 0.70862471 | AY39: 0.26590478 | AZ39: 0.2004662 | BC39: 钟明珠Herceptin SC | BD39: 208
A40: 唐晓玉Itovebi 3mg | C40: I-3mg | D40: 3566.02 | E40: 14.229651 | G40: =_xlfn.XLOOKUP(A40,BC:BC,BD:BD,0) -> 5 | H40: =IFERROR(W40/V40,"") -> 0 | I40: =IFERROR(X40/V40,"") -> 0.35137896 | J40: =IFERROR(X40/W40,"") | K40: =G40-F40 -> 5 | L40: =O40 -> 0 | M40: =IFERROR((X40+Y40)/V40,"") -> 0.35137896 | N40: =K40+L40 -> 5 | P40: =SUM(S40:U40) -> 0 | Q40: =IFERROR((X40+Z40)/V40,"") -> 0.35137896 | R40: =K40+P40 -> 5 | V40: =E40*D40 -> 50743.221 | W40: =F40*D40 -> 0 | X40: =G40*D40 -> 17830.1 | Y40: =L40*D40 -> 0 | Z40: =P40*D40 -> 0 | AB40: 王瑛 | AC40: 1.0733067 | AD40: 0.61099856 | AE40: 0 | AF40: 0 | AG40: 0 | AH40: 0 | AI40: 0.89287836 | AJ40: 0 | AK40: 0 | AN40: 王瑛 | AO40: 1.0866624 | AP40: 0.33753913 | AQ40: 0.5032201 | AR40: 0.18343156 | AS40: 0.82005176 | AT40: 0.2756832 | AV40: 王瑛 | AW40: 1.0866624 | AX40: 0.62652439 | AY40: 0.33753913 | AZ40: 0.14939024 | BC40: 钟明珠Itovebi 3mg | BD40: 38
...

Sheet 渗透率
AC1: 产品品规 | AD1: (多项) | AE1: 纯新转新
B2: 当月GAP支数
B3: 50渗透率 | C3: 80渗透率 | D3: 行标签 | E3: YTD | F3: 24Q4P月均 | G3: 25Q3月均~ | H3: 25Q4月均~ | I3: 25H2月均~ | J3: Jan | K3: Feb | L3: Mar | M3: Apr | N3: May | O3: Jun | P3: YTD渗透率 | Q3: 25Q3渗透率 | R3: 25Q4渗透率 | S3: Q1渗透率 | T3: Q2渗透率 | U3: 1渗透率 | V3: 2渗透率 | W3: 3渗透率 | X3: 4渗透率 | Y3: 5渗透率 | Z3: 6渗透率 | AA3: 季度趋势 | AB3: 月度趋势 | AC3: 行标签 | AD3: 25Q3月均 | AE3: 25Q4月均 | AF3: 26Q1月均 | AG3: 26Q2月均 | AH3: 1月 | AI3: 2月 | AJ3: 3月 | AK3: 4月 | AL3: 5月 | AM3: 6月 | AN3: 季度趋势 | AO3: 月度趋势
B4: =IF(D4="","",M4-F4*0.5) -> -3.3333333 | C4: =IF(D4="","",M4-F4*0.8) -> -5.3333333 | D4: 安溪县医院 | E4: 0 | F4: 6.6666667 | G4: 0 | H4: 0 | I4: 0 | J4: 0 | K4: 0 | L4: 0 | M4: 0 | N4: 0 | O4: 0 | P4: 0 | Q4: 0 | R4: 0 | S4: 0 | T4: 0 | U4: 0 | V4: 0 | W4: 0 | X4: 0 | Y4: 0 | Z4: 0 | AC4: 安溪县医院 | AD4: 0 | AE4: 0 | AF4: 0 | AG4: 0 | AH4: 0 | AI4: 0 | AJ4: 0 | AK4: 0 | AL4: 0 | AM4: 0
B5: =IF(D5="","",M5-F5*0.5) -> -8.3333333 | C5: =IF(D5="","",M5-F5*0.8) -> -13.333333 | D5: 大田县总医院 | E5: 0 | F5: 16.666667 | G5: 0 | H5: 0 | I5: 0 | J5: 0 | K5: 0 | L5: 0 | M5: 0 | N5: 0 | O5: 0 | P5: 0 | Q5: 0 | R5: 0 | S5: 0 | T5: 0 | U5: 0 | V5: 0 | W5: 0 | X5: 0 | Y5: 0 | Z5: 0 | AC5: 大田县总医院 | AD5: 0 | AE5: 0 | AF5: 0 | AG5: 0 | AH5: 0 | AI5: 0 | AJ5: 0 | AK5: 0 | AL5: 0 | AM5: 0
B6: =IF(D6="","",M6-F6*0.5) -> 0 | C6: =IF(D6="","",M6-F6*0.8) -> 0 | D6: 第二军医大学附属长征医院和田路分院 | E6: 0 | F6: 0 | G6: 0 | H6: 0 | I6: 0 | J6: 0 | K6: 0 | L6: 0 | M6: 0 | N6: 0 | O6: 0 | P6: #DIV/0! | Q6: #DIV/0! | R6: #DIV/0! | S6: #DIV/0! | T6: #DIV/0! | U6: #DIV/0! | V6: #DIV/0! | W6: #DIV/0! | X6: #DIV/0! | Y6: #DIV/0! | Z6: #DIV/0! | AC6: 第二军医大学附属长征医院和田路分院 | AD6: 0 | AE6: 0 | AF6: 0 | AG6: 0 | AH6: 0 | AI6: 0 | AJ6: 0 | AK6: 0 | AL6: 0 | AM6: 0
B7: =IF(D7="","",M7-F7*0.5) -> -12.166667 | C7: =IF(D7="","",M7-F7*0.8) -> -20.066667 | D7: 丰城市人民医院 | E7: 7 | F7: 26.333333 | G7: 0 | H7: 0.66666667 | I7: 0.33333333 | J7: 3 | K7: 1 | L7: 2 | M7: 1 | N7: 0 | O7: 0 | P7: 0.066455696 | Q7: 0 | R7: 0.025316456 | S7: 0.075949367 | T7: 0.012658228 | U7: 0.11392405 | V7: 0.037974684 | W7: 0.075949367 | X7: 0.037974684 | Y7: 0 | Z7: 0 | AC7: 丰城市人民医院 | AD7: 0 | AE7: 0 | AF7: 0.33333333 | AG7: 0 | AH7: 0 | AI7: 1 | AJ7: 0 | AK7: 0 | AL7: 0 | AM7: 0
B8: =IF(D8="","",M8-F8*0.5) -> -14 | C8: =IF(D8="","",M8-F8*0.8) -> -24.2 | D8: 福鼎市医院 | E8: 8 | F8: 34 | G8: 2 | H8: 3 | I8: 2.5 | J8: 1 | K8: 2 | L8: 2 | M8: 3 | N8: 0 | O8: 0 | P8: 0.058823529 | Q8: 0.058823529 | R8: 0.088235294 | S8: 0.049019608 | T8: 0.029411765 | U8: 0.029411765 | V8: 0.058823529 | W8: 0.058823529 | X8: 0.088235294 | Y8: 0 | Z8: 0 | AC8: 福鼎市医院 | AD8: 0 | AE8: 0.33333333 | AF8: 0 | AG8: 1 | AH8: 0 | AI8: 0 | AJ8: 0 | AK8: 1 | AL8: 0 | AM8: 0
B9: =IF(D9="","",M9-F9*0.5) -> 0 | C9: =IF(D9="","",M9-F9*0.8) -> 0 | D9: 福建省福清市医院 | E9: 0 | F9: 0 | G9: 0 | H9: 0 | I9: 0 | J9: 0 | K9: 0 | L9: 0 | M9: 0 | N9: 0 | O9: 0 | P9: #DIV/0! | Q9: #DIV/0! | R9: #DIV/0! | S9: #DIV/0! | T9: #DIV/0! | U9: #DIV/0! | V9: #DIV/0! | W9: #DIV/0! | X9: #DIV/0! | Y9: #DIV/0! | Z9: #DIV/0! | AC9: 福建省福清市医院 | AD9: 0 | AE9: 0 | AF9: 0 | AG9: 0 | AH9: 0 | AI9: 0 | AJ9: 0 | AK9: 0 | AL9: 0 | AM9: 0
B10: =IF(D10="","",M10-F10*0.5) -> -2.1666667 | C10: =IF(D10="","",M10-F10*0.8) -> -3.4666667 | D10: 福建省将乐县总医院 | E10: 0 | F10: 4.3333333 | G10: 0 | H10: 0 | I10: 0 | J10: 0 | K10: 0 | L10: 0 | M10: 0 | N10: 0 | O10: 0 | P10: 0 | Q10: 0 | R10: 0 | S10: 0 | T10: 0 | U10: 0 | V10: 0 | W10: 0 | X10: 0 | Y10: 0 | Z10: 0 | AC10: 福建省将乐县总医院 | AD10: 0 | AE10: 0 | AF10: 0 | AG10: 0 | AH10: 0 | AI10: 0 | AJ10: 0 | AK10: 0 | AL10: 0 | AM10: 0
B11: =IF(D11="","",M11-F11*0.5) -> -25.833333 | C11: =IF(D11="","",M11-F11*0.8) -> -64.133333 | D11: 福建省立医院 | E11: 170 | F11: 127.66667 | G11: 42 | H11: 45.333333 | I11: 43.666667 | J11: 47 | K11: 40 | L11: 45 | M11: 38 | N11: 0 | O11: 0 | P11: 0.33289817 | Q11: 0.32898172 | R11: 0.35509138 | S11: 0.34464752 | T11: 0.09921671 | U11: 0.36814621 | V11: 0.31331593 | W11: 0.35248042 | X11: 0.29765013 | Y11: 0 | Z11: 0 | AC11: 福建省立医院 | AD11: 2.6666667 | AE11: 3.6666667 | AF11: 2.3333333 | AG11: 1 | AH11: 1 | AI11: 3 | AJ11: 3 | AK11: 1 | AL11: 0 | AM11: 0
B12: =IF(D12="","",M12-F12*0.5) -> -19 | C12: =IF(D12="","",M12-F12*0.8) -> -33.4 | D12: 福建省南平市第一医院 | E12: 19 | F12: 48 | G12: 3.6666667 | H12: 4.3333333 | I12: 4 | J12: 4 | K12: 4 | L12: 6 | M12: 5 | N12: 0 | O12: 0 | P12: 0.098958333 | Q12: 0.076388889 | R12: 0.090277778 | S12: 0.097222222 | T12: 0.034722222 | U12: 0.083333333 | V12: 0.083333333 | W12: 0.125 | X12: 0.10416667 | Y12: 0 | Z12: 0 | AC12: 福建省南平市第一医院 | AD12: 0.66666667 | AE12: 0.33333333 | AF12: 1 | AG12: 1 | AH12: 1 | AI12: 0 | AJ12: 2 | AK12: 1 | AL12: 0 | AM12: 0
B13: =IF(D13="","",M13-F13*0.5) -> -40.833333 | C13: =IF(D13="","",M13-F13*0.8) -> -113.33333 | D13: 福建省肿瘤医院 | E13: 351 | F13: 241.66667 | G13: 136.66667 | H13: 93.666667 | I13: 115.16667 | J13: 115 | K13: 80 | L13: 76 | M13: 80 | N13: 0 | O13: 0 | P13: 0.36310345 | Q13: 0.56551724 | R13: 0.38758621 | S13: 0.3737931 | T13: 0.11034483 | U13: 0.47586207 | V13: 0.33103448 | W13: 0.31448276 | X13: 0.33103448 | Y13: 0 | Z13: 0 | AC13: 福建省肿瘤医院 | AD13: 16.666667 | AE13: 11.333333 | AF13: 9 | AG13: 3 | AH13: 9 | AI13: 7 | AJ13: 11 | AK13: 3 | AL13: 0 | AM13: 0
B14: =IF(D14="","",M14-F14*0.5) -> -41.5 | C14: =IF(D14="","",M14-F14*0.8) -> -74.8 | D14: 福建医科大学附属第二医院鲤城院区 | E14: 58 | F14: 111 | G14: 13.666667 | H14: 9.3333333 | I14: 11.5 | J14: 14 | K14: 6 | L14: 24 | M14: 14 | N14: 0 | O14: 0 | P14: 0.13063063 | Q14: 0.12312312 | R14: 0.084084084 | S14: 0.13213213 | T14: 0.042042042 | U14: 0.12612613 | V14: 0.054054054 | W14: 0.21621622 | X14: 0.12612613 | Y14: 0 | Z14: 0 | AC14: 福建医科大学附属第二医院鲤城院区 | AD14: 1 | AE14: 0 | AF14: 0.66666667 | AG14: 1 | AH14: 0 | AI14: 1 | AJ14: 1 | AK14: 1 | AL14: 0 | AM14: 0
B15: =IF(D15="","",M15-F15*0.5) -> -37 | C15: =IF(D15="","",M15-F15*0.8) -> -61 | D15: 福建医科大学附属第一医院 | E15: 11 | F15: 80 | G15: 10.333333 | H15: 2.6666667 | I15: 6.5 | J15: 3 | K15: 3 | L15: 2 | M15: 3 | N15: 0 | O15: 0 | P15: 0.034375 | Q15: 0.12916667 | R15: 0.033333333 | S15: 0.033333333 | T15: 0.0125 | U15: 0.0375 | V15: 0.0375 | W15: 0.025 | X15: 0.0375 | Y15: 0 | Z15: 0 | AC15: 福建医科大学附属第一医院 | AD15: 0 | AE15: 0.33333333 | AF15: 0 | AG15: 0 | AH15: 0 | AI15: 0 | AJ15: 0 | AK15: 0 | AL15: 0 | AM15: 0
B16: =IF(D16="","",M16-F16*0.5) -> -7.3333333 | C16: =IF(D16="","",M16-F16*0.8) -> -11.733333 | D16: 福建医科大学附属福州市第一总医院达道院区 | E16: 0 | F16: 14.666667 | G16: 0 | H16: 0 | I16: 0 | J16: 0 | K16: 0 | L16: 0 | M16: 0 | N16: 0 | O16: 0 | P16: 0 | Q16: 0 | R16: 0 | S16: 0 | T16: 0 | U16: 0 | V16: 0 | W16: 0 | X16: 0 | Y16: 0 | Z16: 0 | AC16: 福建医科大学附属福州市第一总医院达道院区 | AD16: 0 | AE16: 0 | AF16: 0 | AG16: 0 | AH16: 0 | AI16: 0 | AJ16: 0 | AK16: 0 | AL16: 0 | AM16: 0
B17: =IF(D17="","",M17-F17*0.5) -> -29 | C17: =IF(D17="","",M17-F17*0.8) -> -125 | D17: 福建医科大学附属协和医院 | E17: 683 | F17: 320 | G17: 148 | H17: 182.66667 | I17: 165.33333 | J17: 159 | K17: 195 | L17: 198 | M17: 131 | N17: 0 | O17: 0 | P17: 0.53359375 | Q17: 0.4625 | R17: 0.57083333 | S17: 0.575 | T17: 0.13645833 | U17: 0.496875 | V17: 0.609375 | W17: 0.61875 | X17: 0.409375 | Y17: 0 | Z17: 0 | AC17: 福建医科大学附属协和医院 | AD17: 24.333333 | AE17: 25.333333 | AF17: 27.666667 | AG17: 15 | AH17: 29 | AI17: 21 | AJ17: 33 | AK17: 15 | AL17: 0 | AM17: 0
B18: =IF(D18="","",M18-F18*0.5) -> -1.5 | C18: =IF(D18="","",M18-F18*0.8) -> -2.4 | D18: 福建医科大学孟超肝胆医院西洪院区 | E18: 0 | F18: 3 | G18: 0 | H18: 0 | I18: 0 | J18: 0 | K18: 0 | L18: 0 | M18: 0 | N18: 0 | O18: 0 | P18: 0 | Q18: 0 | R18: 0 | S18: 0 | T18: 0 | U18: 0 | V18: 0 | W18: 0 | X18: 0 | Y18: 0 | Z18: 0 | AC18: 福建医科大学孟超肝胆医院西洪院区 | AD18: 0 | AE18: 0 | AF18: 0 | AG18: 0 | AH18: 0 | AI18: 0 | AJ18: 0 | AK18: 0 | AL18: 0 | AM18: 0
B19: =IF(D19="","",M19-F19*0.5) -> -4 | C19: =IF(D19="","",M19-F19*0.8) -> -7 | D19: 福州市第二总医院 | E19: 4 | F19: 10 | G19: 0.66666667 | H19: 1.6666667 | I19: 1.1666667 | J19: 1 | K19: 1 | L19: 1 | M19: 1 | N19: 0 | O19: 0 | P19: 0.1 | Q19: 0.066666667 | R19: 0.16666667 | S19: 0.1 | T19: 0.033333333 | U19: 0.1 | V19: 0.1 | W19: 0.1 | X19: 0.1 | Y19: 0 | Z19: 0 | AC19: 福州市第二总医院 | AD19: 0 | AE19: 0 | AF19: 0 | AG19: 0 | AH19: 0 | AI19: 0 | AJ19: 0 | AK19: 0 | AL19: 0 | AM19: 0
B20: =IF(D20="","",M20-F20*0.5) -> 0 | C20: =IF(D20="","",M20-F20*0.8) -> 0 | D20: 福州市第二总医院奥体院区 | E20: 0 | F20: 0 | G20: 0 | H20: 0 | I20: 0 | J20: 0 | K20: 0 | L20: 0 | M20: 0 | N20: 0 | O20: 0 | P20: #DIV/0! | Q20: #DIV/0! | R20: #DIV/0! | S20: #DIV/0! | T20: #DIV/0! | U20: #DIV/0! | V20: #DIV/0! | W20: #DIV/0! | X20: #DIV/0! | Y20: #DIV/0! | Z20: #DIV/0! | AC20: 福州市第二总医院奥体院区 | AD20: 0 | AE20: 0 | AF20: 0 | AG20: 0 | AH20: 0 | AI20: 0 | AJ20: 0 | AK20: 0 | AL20: 0 | AM20: 0
B21: =IF(D21="","",M21-F21*0.5) -> 0 | C21: =IF(D21="","",M21-F21*0.8) -> 0 | D21: 福州市第七医院 | E21: 0 | F21: 0 | G21: 0 | H21: 0 | I21: 0 | J21: 0 | K21: 0 | L21: 0 | M21: 0 | N21: 0 | O21: 0 | P21: #DIV/0! | Q21: #DIV/0! | R21: #DIV/0! | S21: #DIV/0! | T21: #DIV/0! | U21: #DIV/0! | V21: #DIV/0! | W21: #DIV/0! | X21: #DIV/0! | Y21: #DIV/0! | Z21: #DIV/0! | AC21: 福州市第七医院 | AD21: 0 | AE21: 0 | AF21: 0 | AG21: 0 | AH21: 0 | AI21: 0 | AJ21: 0 | AK21: 0 | AL21: 0 | AM21: 0
B22: =IF(D22="","",M22-F22*0.5) -> -4.8333333 | C22: =IF(D22="","",M22-F22*0.8) -> -8.3333333 | D22: 抚州市第一人民医院附属医院院区 | E22: 4 | F22: 11.666667 | G22: 2 | H22: 1 | I22: 1.5 | J22: 0 | K22: 2 | L22: 1 | M22: 1 | N22: 0 | O22: 0 | P22: 0.085714286 | Q22: 0.17142857 | R22: 0.085714286 | S22: 0.085714286 | T22: 0.028571429 | U22: 0 | V22: 0.17142857 | W22: 0.085714286 | X22: 0.085714286 | Y22: 0 | Z22: 0 | AC22: 抚州市第一人民医院附属医院院区 | AD22: 0 | AE22: 0 | AF22: 0 | AG22: 0 | AH22: 0 | AI22: 0 | AJ22: 0 | AK22: 0 | AL22: 0 | AM22: 0
B23: =IF(D23="","",M23-F23*0.5) -> -38 | C23: =IF(D23="","",M23-F23*0.8) -> -60.8 | D23: 复旦大学附属妇产科医院黄浦院区 | E23: 50 | F23: 76 | G23: 88.666667 | H23: 81.666667 | I23: 85.166667 | J23: 20 | K23: 30 | L23: 0 | M23: 0 | N23: 0 | O23: 0 | P23: 0.16447368 | Q23: 1.1666667 | R23: 1.0745614 | S23: 0.21929825 | T23: 0 | U23: 0.26315789 | V23: 0.39473684 | W23: 0 | X23: 0 | Y23: 0 | Z23: 0 | AC23: 复旦大学附属妇产科医院黄浦院区 | AD23: 4 | AE23: 0.66666667 | AF23: 3.3333333 | AG23: 1 | AH23: 4 | AI23: 2 | AJ23: 4 | AK23: 1 | AL23: 0 | AM23: 0
B24: =IF(D24="","",M24-F24*0.5) -> 12.833333 | C24: =IF(D24="","",M24-F24*0.8) -> 11.533333 | D24: 复旦大学附属妇产科医院长三角一体化示范区青浦分院 | E24: 36 | F24: 4.3333333 | G24: 9.6666667 | H24: 12.333333 | I24: 11 | J24: 3 | K24: 12 | L24: 6 | M24: 15 | N24: 0 | O24: 0 | P24: 2.0769231 | Q24: 2.2307692 | R24: 2.8461538 | S24: 1.6153846 | T24: 1.1538462 | U24: 0.69230769 | V24: 2.7692308 | W24: 1.3846154 | X24: 3.4615385 | Y24: 0 | Z24: 0 | AC24: 复旦大学附属妇产科医院长三角一体化示范区青浦分院 | AD24: 0 | AE24: 0 | AF24: 0 | AG24: 0 | AH24: 0 | AI24: 0 | AJ24: 0 | AK24: 0 | AL24: 0 | AM24: 0
B25: =IF(D25="","",M25-F25*0.5) -> -16 | C25: =IF(D25="","",M25-F25*0.8) -> -35.8 | D25: 复旦大学附属华东医院 | E25: 84 | F25: 66 | G25: 14 | H25: 15.666667 | I25: 14.833333 | J25: 16 | K25: 33 | L25: 18 | M25: 17 | N25: 0 | O25: 0 | P25: 0.31818182 | Q25: 0.21212121 | R25: 0.23737374 | S25: 0.33838384 | T25: 0.085858586 | U25: 0.24242424 | V25: 0.5 | W25: 0.27272727 | X25: 0.25757576 | Y25: 0 | Z25: 0 | AC25: 复旦大学附属华东医院 | AD25: 2.3333333 | AE25: 1 | AF25: 0.33333333 | AG25: 0 | AH25: 1 | AI25: 0 | AJ25: 0 | AK25: 0 | AL25: 0 | AM25: 0
B26: =IF(D26="","",M26-F26*0.5) -> -56.833333 | C26: =IF(D26="","",M26-F26*0.8) -> -108.93333 | D26: 复旦大学附属华山医院总院 | E26: 419 | F26: 173.66667 | G26: 161 | H26: 75.666667 | I26: 118.33333 | J26: 93 | K26: 137 | L26: 159 | M26: 30 | N26: 0 | O26: 0 | P26: 0.60316699 | Q26: 0.92706334 | R26: 0.43570058 | S26: 0.74664107 | T26: 0.057581574 | U26: 0.53550864 | V26: 0.78886756 | W26: 0.91554702 | X26: 0.17274472 | Y26: 0 | Z26: 0 | AC26: 复旦大学附属华山医院总院 | AD26: 7 | AE26: 0 | AF26: 2.3333333 | AG26: 3 | AH26: 2 | AI26: 2 | AJ26: 3 | AK26: 3 | AL26: 0 | AM26: 0
B27: =IF(D27="","",M27-F27*0.5) -> 0 | C27: =IF(D27="","",M27-F27*0.8) -> 0 | D27: 复旦大学附属金山医院 | E27: 0 | F27: 0 | G27: 0.33333333 | H27: 0 | I27: 0.16666667 | J27: 0 | K27: 0 | L27: 0 | M27: 0 | N27: 0 | O27: 0 | P27: #DIV/0! | Q27: #DIV/0! | R27: #DIV/0! | S27: #DIV/0! | T27: #DIV/0! | U27: #DIV/0! | V27: #DIV/0! | W27: #DIV/0! | X27: #DIV/0! | Y27: #DIV/0! | Z27: #DIV/0! | AC27: 复旦大学附属金山医院 | AD27: 0 | AE27: 0 | AF27: 0 | AG27: 0 | AH27: 0 | AI27: 0 | AJ27: 0 | AK27: 0 | AL27: 0 | AM27: 0
B28: =IF(D28="","",M28-F28*0.5) -> -11 | C28: =IF(D28="","",M28-F28*0.8) -> -20 | D28: 复旦大学附属闵行医院 | E28: 17 | F28: 30 | G28: 6 | H28: 3.6666667 | I28: 4.8333333 | J28: 5 | K28: 6 | L28: 2 | M28: 4 | N28: 0 | O28: 0 | P28: 0.14166667 | Q28: 0.2 | R28: 0.12222222 | S28: 0.14444444 | T28: 0.044444444 | U28: 0.16666667 | V28: 0.2 | W28: 0.066666667 | X28: 0.13333333 | Y28: 0 | Z28: 0 | AC28: 复旦大学附属闵行医院 | AD28: 0.33333333 | AE28: 0.66666667 | AF28: 0.33333333 | AG28: 0 | AH28: 0 | AI28: 0 | AJ28: 1 | AK28: 0 | AL28: 0 | AM28: 0
B29: =IF(D29="","",M29-F29*0.5) -> -10 | C29: =IF(D29="","",M29-F29*0.8) -> -16 | D29: 复旦大学附属浦东医院 | E29: 2 | F29: 20 | G29: 5 | H29: -2.3333333 | I29: 1.3333333 | J29: 2 | K29: 0 | L29: 0 | M29: 0 | N29: 0 | O29: 0 | P29: 0.025 | Q29: 0.25 | R29: -0.11666667 | S29: 0.033333333 | T29: 0 | U29: 0.1 | V29: 0 | W29: 0 | X29: 0 | Y29: 0 | Z29: 0 | AC29: 复旦大学附属浦东医院 | AD29: 0.33333333 | AE29: 0.33333333 | AF29: 0 | AG29: 0 | AH29: 0 | AI29: 0 | AJ29: 0 | AK29: 0 | AL29: 0 | AM29: 0
B30: =IF(D30="","",M30-F30*0.5) -> 34.666667 | C30: =IF(D30="","",M30-F30*0.8) -> -15.333333 | D30: 复旦大学附属中山医院 | E30: 654 | F30: 166.66667 | G30: 181.66667 | H30: 122.33333 | I30: 152 | J30: 182 | K30: 162 | L30: 192 | M30: 118 | N30: 0 | O30: 0 | P30: 0.981 | Q30: 1.09 | R30: 0.734 | S30: 1.072 | T30: 0.236 | U30: 1.092 | V30: 0.972 | W30: 1.152 | X30: 0.708 | Y30: 0 | Z30: 0 | AC30: 复旦大学附属中山医院 | AD30: 11 | AE30: 11 | AF30: 12 | AG30: 7 | AH30: 15 | AI30: 9 | AJ30: 12 | AK30: 7 | AL30: 0 | AM30: 0
B31: =IF(D31="","",M31-F31*0.5) -> 18.5 | C31: =IF(D31="","",M31-F31*0.8) -> 13.4 | D31: 复旦大学附属中山医院闵行梅陇院区 | E31: 95 | F31: 17 | G31: 17.333333 | H31: 10 | I31: 13.666667 | J31: 12 | K31: 22 | L31: 34 | M31: 27 | N31: 0 | O31: 0 | P31: 1.3970588 | Q31: 1.0196078 | R31: 0.58823529 | S31: 1.3333333 | T31: 0.52941176 | U31: 0.70588235 | V31: 1.2941176 | W31: 2 | X31: 1.5882353 | Y31: 0 | Z31: 0 | AC31: 复旦大学附属中山医院闵行梅陇院区 | AD31: 0 | AE31: 0 | AF31: 0.66666667 | AG31: 2 | AH31: 0 | AI31: 2 | AJ31: 0 | AK31: 2 | AL31: 0 | AM31: 0
B32: =IF(D32="","",M32-F32*0.5) -> -4 | C32: =IF(D32="","",M32-F32*0.8) -> -6.4 | D32: 复旦大学附属中山医院青浦分院 | E32: 0 | F32: 8 | G32: 0 | H32: 0 | I32: 0 | J32: 0 | K32: 0 | L32: 0 | M32: 0 | N32: 0 | O32: 0 | P32: 0 | Q32: 0 | R32: 0 | S32: 0 | T32: 0 | U32: 0 | V32: 0 | W32: 0 | X32: 0 | Y32: 0 | Z32: 0 | AC32: 复旦大学附属中山医院青浦分院 | AD32: 0 | AE32: 0 | AF32: 0 | AG32: 0 | AH32: 0 | AI32: 0 | AJ32: 0 | AK32: 0 | AL32: 0 | AM32: 0
B33: =IF(D33="","",M33-F33*0.5) -> 10.166667 | C33: =IF(D33="","",M33-F33*0.8) -> 4.2666667 | D33: 复旦大学附属中山医院厦门医院 | E33: 73 | F33: 19.666667 | G33: 11 | H33: 8 | I33: 9.5 | J33: 13 | K33: 15 | L33: 25 | M33: 20 | N33: 0 | O33: 0 | P33: 0.9279661 | Q33: 0.55932203 | R33: 0.40677966 | S33: 0.89830508 | T33: 0.33898305 | U33: 0.66101695 | V33: 0.76271186 | W33: 1.2711864 | X33: 1.0169492 | Y33: 0 | Z33: 0 | AC33: 复旦大学附属中山医院厦门医院 | AD33: 0.66666667 | AE33: 0 | AF33: 0.33333333 | AG33: 6 | AH33: 0 | AI33: 0 | AJ33: 1 | AK33: 6 | AL33: 0 | AM33: 0
B34: =IF(D34="","",M34-F34*0.5) -> -3.3333333 | C34: =IF(D34="","",M34-F34*0.8) -> -8.3333333 | D34: 复旦大学附属肿瘤医院厦门医院 | E34: 56 | F34: 16.666667 | G34: 18 | H34: 13 | I34: 15.5 | J34: 10 | K34: 31 | L34: 10 | M34: 5 | N34: 0 | O34: 0 | P34: 0.84 | Q34: 1.08 | R34: 0.78 | S34: 1.02 | T34: 0.1 | U34: 0.6 | V34: 1.86 | W34: 0.6 | X34: 0.3 | Y34: 0 | Z34: 0 | AC34: 复旦大学附属肿瘤医院厦门医院 | AD34: 0 | AE34: 0 | AF34: 0 | AG34: 1 | AH34: 0 | AI34: 0 | AJ34: 0 | AK34: 1 | AL34: 0 | AM34: 0
B35: =IF(D35="","",M35-F35*0.5) -> -10.166667 | C35: =IF(D35="","",M35-F35*0.8) -> -70.266667 | D35: 赣南医科大学第一附属医院章贡院区 | E35: 409 | F35: 200.33333 | G35: 96.666667 | H35: 104 | I35: 100.33333 | J35: 111 | K35: 96 | L35: 112 | M35: 90 | N35: 0 | O35: 0 | P35: 0.51039933 | Q35: 0.48252912 | R35: 0.51913478 | S35: 0.53078203 | T35: 0.14975042 | U35: 0.55407654 | V35: 0.47920133 | W35: 0.55906822 | X35: 0.44925125 | Y35: 0 | Z35: 0 | AC35: 赣南医科大学第一附属医院章贡院区 | AD35: 8 | AE35: 7 | AF35: 3.6666667 | AG35: 2 | AH35: 3 | AI35: 4 | AJ35: 4 | AK35: 2 | AL35: 0 | AM35: 0
B36: =IF(D36="","",M36-F36*0.5) -> -1.5 | C36: =IF(D36="","",M36-F36*0.8) -> -3 | D36: 赣西肿瘤医院 | E36: 5 | F36: 5 | G36: 0.33333333 | H36: 2 | I36: 1.1666667 | J36: 1 | K36: 0 | L36: 3 | M36: 1 | N36: 0 | O36: 0 | P36: 0.25 | Q36: 0.066666667 | R36: 0.4 | S36: 0.26666667 | T36: 0.066666667 | U36: 0.2 | V36: 0 | W36: 0.6 | X36: 0.2 | Y36: 0 | Z36: 0 | AC36: 赣西肿瘤医院 | AD36: 0.33333333 | AE36: 0 | AF36: 0.33333333 | AG36: 0 | AH36: 0 | AI36: 0 | AJ36: 1 | AK36: 0 | AL36: 0 | AM36: 0
B37: =IF(D37="","",M37-F37*0.5) -> 13.833333 | C37: =IF(D37="","",M37-F37*0.8) -> 11.333333 | D37: 赣州市妇幼保健院大公路院区 | E37: 56 | F37: 8.3333333 | G37: 13.333333 | H37: 3.3333333 | I37: 8.3333333 | J37: 13 | K37: 21 | L37: 4 | M37: 18 | N37: 0 | O37: 0 | P37: 1.68 | Q37: 1.6 | R37: 0.4 | S37: 1.52 | T37: 0.72 | U37: 1.56 | V37: 2.52 | W37: 0.48 | X37: 2.16 | Y37: 0 | Z37: 0 | AC37: 赣州市妇幼保健院大公路院区 | AD37: 0.66666667 | AE37: 0 | AF37: 1.6666667 | AG37: 1 | AH37: 3 | AI37: 1 | AJ37: 1 | AK37: 1 | AL37: 0 | AM37: 0
B38: =IF(D38="","",M38-F38*0.5) -> -23.5 | C38: =IF(D38="","",M38-F38*0.8) -> -50.8 | D38: 赣州市人民医院北院区 | E38: 112 | F38: 91 | G38: 32.333333 | H38: 31.666667 | I38: 32 | J38: 33 | K38: 29 | L38: 28 | M38: 22 | N38: 0 | O38: 0 | P38: 0.30769231 | Q38: 0.35531136 | R38: 0.34798535 | S38: 0.32967033 | T38: 0.080586081 | U38: 0.36263736 | V38: 0.31868132 | W38: 0.30769231 | X38: 0.24175824 | Y38: 0 | Z38: 0 | AC38: 赣州市人民医院北院区 | AD38: 0.33333333 | AE38: 2.3333333 | AF38: 1.3333333 | AG38: 0 | AH38: 0 | AI38: 2 | AJ38: 2 | AK38: 0 | AL38: 0 | AM38: 0
